Workbook

Sheet 수동정렬

Sheet 전적확인
A1: ID | B1: 드루_승 | C1: 드루_패 | D1: 어쎄_승 | E1: 어쎄_패 | F1: 네크_승 | G1: 네크_패 | H1: 슴딘_승 | I1: 슴딘_패 | J1: 종합_승 | K1: 종합_패 | L1: 종합_승률 | M1: 드루_승률 | N1: 어쎄_승률 | O1: 네크_승률 | P1: 슴딘_승률 | Q1: 순위 | R1: 점수 | S1: 날짜 | T1: 히든여부 | U1: 배치승리수 | V1: 티어 | W1: 이전 순위 | X1: 순위 증감
A2: 원 | B2: 5 | C2: 3 | D2: 2 | E2: 2 | F2: 6 | G2: 0 | H2: 5 | I2: 2 | J2: =B2+D2+F2+H2 -> 18 | K2: =C2+E2+G2+I2 -> 7 | L2: =ROUND(IFERROR(J2/(J2+K2),0)*100,1) -> 72 | M2: =ROUND(IFERROR(B2/(B2+C2),0)*100,1) -> 62.5 | N2: =ROUND(IFERROR(D2/(D2+E2),0)*100,1) -> 50 | O2: =ROUND(IFERROR(F2/(F2+G2),0)*100,1) -> 100 | P2: =ROUND(IFERROR(H2/(I2+H2),0)*100,1) -> 71.4 | Q2: =IF(A2="미등록", "", COUNTIF(A$2:A2,"<>미등록")) -> 1 | R2: 1359 | S2: 46061.976 | T2: N | U2: 14 | V2: {=IFERROR(INDEX('사용자목록'!O:O, MATCH(A2, '사용자목록'!A:A, 0)),"아이언")} -> 마스터 | W2: 1 | X2: =if(Q2<W2, "🔼", if(Q2>W2, "🔽", ""))
A3: 깡패 | B3: 8 | C3: 9 | D3: 11 | E3: 7 | F3: 6 | G3: 2 | H3: 7 | I3: 4 | J3: =B3+D3+F3+H3 -> 32 | K3: =C3+E3+G3+I3 -> 22 | L3: =ROUND(IFERROR(J3/(J3+K3),0)*100,1) -> 59.3 | M3: =ROUND(IFERROR(B3/(B3+C3),0)*100,1) -> 47.1 | N3: =ROUND(IFERROR(D3/(D3+E3),0)*100,1) -> 61.1 | O3: =ROUND(IFERROR(F3/(F3+G3),0)*100,1) -> 75 | P3: =ROUND(IFERROR(H3/(I3+H3),0)*100,1) -> 63.6 | Q3: =IF(A3="미등록", "", COUNTIF(A$2:A3,"<>미등록")) -> 2 | R3: 1316 | S3: 46063.018 | T3: N | U3: 12 | V3: {=IFERROR(INDEX('사용자목록'!O:O, MATCH(A3, '사용자목록'!A:A, 0)),"아이언")} -> 다이아 | W3: 2 | X3: =if(Q3<W3, "🔼", if(Q3>W3, "🔽", ""))
A4: 테리 | B4: 15 | C4: 8 | D4: 9 | E4: 9 | F4: 11 | G4: 8 | H4: 0 | I4: 0 | J4: =B4+D4+F4+H4 -> 35 | K4: =C4+E4+G4+I4 -> 25 | L4: =ROUND(IFERROR(J4/(J4+K4),0)*100,1) -> 58.3 | M4: =ROUND(IFERROR(B4/(B4+C4),0)*100,1) -> 65.2 | N4: =ROUND(IFERROR(D4/(D4+E4),0)*100,1) -> 50 | O4: =ROUND(IFERROR(F4/(F4+G4),0)*100,1) -> 57.9 | P4: =ROUND(IFERROR(H4/(I4+H4),0)*100,1) -> 0 | Q4: =IF(A4="미등록", "", COUNTIF(A$2:A4,"<>미등록")) -> 3 | R4: 1297 | S4: 46062.984 | T4: N | U4: 10 | V4: {=IFERROR(INDEX('사용자목록'!O:O, MATCH(A4, '사용자목록'!A:A, 0)),"아이언")} -> 마스터 | W4: 3 | X4: =if(Q4<W4, "🔼", if(Q4>W4, "🔽", ""))
A5: 규식 | B5: 0 | C5: 0 | D5: 6 | E5: 3 | F5: 5 | G5: 3 | H5: 9 | I5: 4 | J5: =B5+D5+F5+H5 -> 20 | K5: =C5+E5+G5+I5 -> 10 | L5: =ROUND(IFERROR(J5/(J5+K5),0)*100,1) -> 66.7 | M5: =ROUND(IFERROR(B5/(B5+C5),0)*100,1) -> 0 | N5: =ROUND(IFERROR(D5/(D5+E5),0)*100,1) -> 66.7 | O5: =ROUND(IFERROR(F5/(F5+G5),0)*100,1) -> 62.5 | P5: =ROUND(IFERROR(H5/(I5+H5),0)*100,1) -> 69.2 | Q5: =IF(A5="미등록", "", COUNTIF(A$2:A5,"<>미등록")) -> 4 | R5: 1279 | S5: 46063.018 | T5: N | U5: 12 | V5: {=IFERROR(INDEX('사용자목록'!O:O, MATCH(A5, '사용자목록'!A:A, 0)),"아이언")} -> 마스터 | W5: 4 | X5: =if(Q5<W5, "🔼", if(Q5>W5, "🔽", ""))
A6: 참치 | B6: 5 | C6: 2 | D6: 3 | E6: 3 | F6: 2 | G6: 1 | H6: 1 | I6: 3 | J6: =B6+D6+F6+H6 -> 11 | K6: =C6+E6+G6+I6 -> 9 | L6: =ROUND(IFERROR(J6/(J6+K6),0)*100,1) -> 55 | M6: =ROUND(IFERROR(B6/(B6+C6),0)*100,1) -> 71.4 | N6: =ROUND(IFERROR(D6/(D6+E6),0)*100,1) -> 50 | O6: =ROUND(IFERROR(F6/(F6+G6),0)*100,1) -> 66.7 | P6: =ROUND(IFERROR(H6/(I6+H6),0)*100,1) -> 25 | Q6: =IF(A6="미등록", "", COUNTIF(A$2:A6,"<>미등록")) -> 5 | R6: 1264 | S6: 46062.21 | T6: N | U6: 11 | V6: {=IFERROR(INDEX('사용자목록'!O:O, MATCH(A6, '사용자목록'!A:A, 0)),"아이언")} -> 아이언 | W6: 5 | X6: =if(Q6<W6, "🔼", if(Q6>W6, "🔽", ""))
A7: 신형만 | B7: 5 | C7: 7 | D7: 8 | E7: 6 | F7: 4 | G7: 8 | H7: 8 | I7: 9 | J7: =B7+D7+F7+H7 -> 25 | K7: =C7+E7+G7+I7 -> 30 | L7: =ROUND(IFERROR(J7/(J7+K7),0)*100,1) -> 45.5 | M7: =ROUND(IFERROR(B7/(B7+C7),0)*100,1) -> 41.7 | N7: =ROUND(IFERROR(D7/(D7+E7),0)*100,1) -> 57.1 | O7: =ROUND(IFERROR(F7/(F7+G7),0)*100,1) -> 33.3 | P7: =ROUND(IFERROR(H7/(I7+H7),0)*100,1) -> 47.1 | Q7: =IF(A7="미등록", "", COUNTIF(A$2:A7,"<>미등록")) -> 6 | R7: 1204 | S7: 46063.018 | T7: N | U7: 7 | V7: {=IFERROR(INDEX('사용자목록'!O:O, MATCH(A7, '사용자목록'!A:A, 0)),"아이언")} -> 골드 | W7: 6 | X7: =if(Q7<W7, "🔼", if(Q7>W7, "🔽", ""))
A8: 넘버 | B8: 0 | C8: 4 | D8: 4 | E8: 3 | F8: 4 | G8: 1 | H8: 2 | I8: 4 | J8: =B8+D8+F8+H8 -> 10 | K8: =C8+E8+G8+I8 -> 12 | L8: =ROUND(IFERROR(J8/(J8+K8),0)*100,1) -> 45.5 | M8: =ROUND(IFERROR(B8/(B8+C8),0)*100,1) -> 0 | N8: =ROUND(IFERROR(D8/(D8+E8),0)*100,1) -> 57.1 | O8: =ROUND(IFERROR(F8/(F8+G8),0)*100,1) -> 80 | P8: =ROUND(IFERROR(H8/(I8+H8),0)*100,1) -> 33.3 | Q8: =IF(A8="미등록", "", COUNTIF(A$2:A8,"<>미등록")) -> 7 | R8: 1204 | S8: 46052.896 | T8: N | U8: 11 | V8: {=IFERROR(INDEX('사용자목록'!O:O, MATCH(A8, '사용자목록'!A:A, 0)),"아이언")} -> 마스터 | W8: 7 | X8: =if(Q8<W8, "🔼", if(Q8>W8, "🔽", ""))
A9: 학생 | B9: 6 | C9: 7 | D9: 7 | E9: 10 | F9: 7 | G9: 5 | H9: 5 | I9: 5 | J9: =B9+D9+F9+H9 -> 25 | K9: =C9+E9+G9+I9 -> 27 | L9: =ROUND(IFERROR(J9/(J9+K9),0)*100,1) -> 48.1 | M9: =ROUND(IFERROR(B9/(B9+C9),0)*100,1) -> 46.2 | N9: =ROUND(IFERROR(D9/(D9+E9),0)*100,1) -> 41.2 | O9: =ROUND(IFERROR(F9/(F9+G9),0)*100,1) -> 58.3 | P9: =ROUND(IFERROR(H9/(I9+H9),0)*100,1) -> 50 | Q9: =IF(A9="미등록", "", COUNTIF(A$2:A9,"<>미등록")) -> 8 | R9: 1189 | S9: 46063.018 | T9: N | U9: 11 | V9: {=IFERROR(INDEX('사용자목록'!O:O, MATCH(A9, '사용자목록'!A:A, 0)),"아이언")} -> 아이언 | W9: 8 | X9: =if(Q9<W9, "🔼", if(Q9>W9, "🔽", ""))
A10: 기재 | B10: 5 | C10: 2 | D10: 0 | E10: 0 | F10: 3 | G10: 6 | H10: 1 | I10: 6 | J10: =B10+D10+F10+H10 -> 9 | K10: =C10+E10+G10+I10 -> 14 | L10: =ROUND(IFERROR(J10/(J10+K10),0)*100,1) -> 39.1 | M10: =ROUND(IFERROR(B10/(B10+C10),0)*100,1) -> 71.4 | N10: =ROUND(IFERROR(D10/(D10+E10),0)*100,1) -> 0 | O10: =ROUND(IFERROR(F10/(F10+G10),0)*100,1) -> 33.3 | P10: =ROUND(IFERROR(H10/(I10+H10),0)*100,1) -> 14.3 | Q10: =IF(A10="미등록", "", COUNTIF(A$2:A10,"<>미등록")) -> 9 | R10: 1177 | S10: 46062.902 | T10: N | U10: 8 | V10: {=IFERROR(INDEX('사용자목록'!O:O, MATCH(A10, '사용자목록'!A:A, 0)),"아이언")} -> 플래티넘 | W10: 9 | X10: =if(Q10<W10, "🔼", if(Q10>W10, "🔽", ""))
A11: ACDC | B11: 9 | C11: 5 | D11: 1 | E11: 4 | F11: 6 | G11: 6 | H11: 7 | I11: 11 | J11: =B11+D11+F11+H11 -> 23 | K11: =C11+E11+G11+I11 -> 26 | L11: =ROUND(IFERROR(J11/(J11+K11),0)*100,1) -> 46.9 | M11: =ROUND(IFERROR(B11/(B11+C11),0)*100,1) -> 64.3 | N11: =ROUND(IFERROR(D11/(D11+E11),0)*100,1) -> 20 | O11: =ROUND(IFERROR(F11/(F11+G11),0)*100,1) -> 50 | P11: =ROUND(IFERROR(H11/(I11+H11),0)*100,1) -> 38.9 | Q11: =IF(A11="미등록", "", COUNTIF(A$2:A11,"<>미등록")) -> 10 | R11: 1149 | S11: 46062.21 | T11: N | U11: 4 | V11: {=IFERROR(INDEX('사용자목록'!O:O, MATCH(A11, '사용자목록'!A:A, 0)),"아이언")} -> 실버 | W11: 10 | X11: =if(Q11<W11, "🔼", if(Q11>W11, "🔽", ""))
A12: 짱구 | B12: 1 | C12: 3 | D12: 9 | E12: 6 | F12: 4 | G12: 7 | H12: 5 | I12: 6 | J12: =B12+D12+F12+H12 -> 19 | K12: =C12+E12+G12+I12 -> 22 | L12: =ROUND(IFERROR(J12/(J12+K12),0)*100,1) -> 46.3 | M12: =ROUND(IFERROR(B12/(B12+C12),0)*100,1) -> 25 | N12: =ROUND(IFERROR(D12/(D12+E12),0)*100,1) -> 60 | O12: =ROUND(IFERROR(F12/(F12+G12),0)*100,1) -> 36.4 | P12: =ROUND(IFERROR(H12/(I12+H12),0)*100,1) -> 45.5 | Q12: =IF(A12="미등록", "", COUNTIF(A$2:A12,"<>미등록")) -> 11 | R12: 1115 | S12: 46062.21 | T12: N | U12: 10 | V12: {=IFERROR(INDEX('사용자목록'!O:O, MATCH(A12, '사용자목록'!A:A, 0)),"아이언")} -> 골드 | W12: 11 | X12: =if(Q12<W12, "🔼", if(Q12>W12, "🔽", ""))
A13: 한메 | B13: 0 | C13: 4 | D13: 0 | E13: 0 | F13: 3 | G13: 2 | H13: 7 | I13: 3 | J13: =B13+D13+F13+H13 -> 10 | K13: =C13+E13+G13+I13 -> 9 | L13: =ROUND(IFERROR(J13/(J13+K13),0)*100,1) -> 52.6 | M13: =ROUND(IFERROR(B13/(B13+C13),0)*100,1) -> 0 | N13: =ROUND(IFERROR(D13/(D13+E13),0)*100,1) -> 0 | O13: =ROUND(IFERROR(F13/(F13+G13),0)*100,1) -> 60 | P13: =ROUND(IFERROR(H13/(I13+H13),0)*100,1) -> 70 | Q13: =IF(A13="미등록", "", COUNTIF(A$2:A13,"<>미등록")) -> 12 | R13: 0 | S13: 46062.984 | T13: N | U13: 6 | V13: {=IFERROR(INDEX('사용자목록'!O:O, MATCH(A13, '사용자목록'!A:A, 0)),"아이언")} -> 골드 | W13: 12 | X13: =if(Q13<W13, "🔼", if(Q13>W13, "🔽", ""))
... A22: 노픽업 | B22: 0 | C22: 0 | D22: 0 | E22: 3 | F22: 0 | G22: 3 | H22: 1 | I22: 1 | J22: =B22+D22+F22+H22 -> 1 | K22: =C22+E22+G22+I22 -> 7 | L22: =ROUND(IFERROR(J22/(J22+K22),0)*100,1) -> 12.5 | M22: =ROUND(IFERROR(B22/(B22+C22),0)*100,1) -> 0 | N22: =ROUND(IFERROR(D22/(D22+E22),0)*100,1) -> 0 | O22: =ROUND(IFERROR(F22/(F22+G22),0)*100,1) -> 0 | P22: =ROUND(IFERROR(H22/(I22+H22),0)*100,1) -> 50 | Q22: =IF(A22="미등록", "", COUNTIF(A$2:A22,"<>미등록")) -> 21 | R22: 0 | S22: 45987.885 | T22: N | U22: 0 | V22: {=IFERROR(INDEX('사용자목록'!O:O, MATCH(A22, '사용자목록'!A:A, 0)),"아이언")} -> 실버 | W22: 21 | X22: =if(Q22<W22, "🔼", if(Q22>W22, "🔽", ""))
A23: 미등록 | B23: 0 | C23: 0 | D23: 0 | E23: 0 | F23: 0 | G23: 0 | H23: 0 | I23: 0 | J23: =B23+D23+F23+H23 -> 0 | K23: =C23+E23+G23+I23 -> 0 | L23: =ROUND(IFERROR(J23/(J23+K23),0)*100,1) -> 0 | M23: =ROUND(IFERROR(B23/(B23+C23),0)*100,1) -> 0 | N23: =ROUND(IFERROR(D23/(D23+E23),0)*100,1) -> 0 | O23: =ROUND(IFERROR(F23/(F23+G23),0)*100,1) -> 0 | P23: =ROUND(IFERROR(H23/(I23+H23),0)*100,1) -> 0 | Q23: =IF(A23="미등록", "", COUNTIF(A$2:A23,"<>미등록")) | R23: 0 | S23: 45953.033 | T23: Y | U23: 0 | V23: {=IFERROR(INDEX('사용자목록'!O:O, MATCH(A23, '사용자목록'!A:A, 0)),"아이언")} -> 아이언 | X23: =if(Q23<W23, "🔼", if(Q23>W23, "🔽", ""))
A24: 웅 | B24: 0 | C24: 0 | D24: 0 | E24: 0 | F24: 0 | G24: 1 | H24: 0 | I24: 1 | J24: =B24+D24+F24+H24 -> 0 | K24: =C24+E24+G24+I24 -> 2 | L24: =ROUND(IFERROR(J24/(J24+K24),0)*100,1) -> 0 | M24: =ROUND(IFERROR(B24/(B24+C24),0)*100,1) -> 0 | N24: =ROUND(IFERROR(D24/(D24+E24),0)*100,1) -> 0 | O24: =ROUND(IFERROR(F24/(F24+G24),0)*100,1) -> 0 | P24: =ROUND(IFERROR(H24/(I24+H24),0)*100,1) -> 0 | Q24: =IF(A24="미등록", "", COUNTIF(A$2:A24,"<>미등록")) -> 22 | R24: 0 | S24: 46061.976 | T24: N | U24: 0 | V24: {=IFERROR(INDEX('사용자목록'!O:O, MATCH(A24, '사용자목록'!A:A, 0)),"아이언")} -> 아이언 | W24: 22 | X24: =if(Q24<W24, "🔼", if(Q24>W24, "🔽", ""))
A25: 수련 | B25: 0 | C25: 0 | D25: 0 | E25: 1 | F25: 0 | G25: 1 | H25: 0 | I25: 0 | J25: =B25+D25+F25+H25 -> 0 | K25: =C25+E25+G25+I25 -> 2 | L25: =ROUND(IFERROR(J25/(J25+K25),0)*100,1) -> 0 | M25: =ROUND(IFERROR(B25/(B25+C25),0)*100,1) -> 0 | N25: =ROUND(IFERROR(D25/(D25+E25),0)*100,1) -> 0 | O25: =ROUND(IFERROR(F25/(F25+G25),0)*100,1) -> 0 | P25: =ROUND(IFERROR(H25/(I25+H25),0)*100,1) -> 0 | Q25: =IF(A25="미등록", "", COUNTIF(A$2:A25,"<>미등록")) -> 23 | R25: 0 | S25: 46062.21 | T25: N | U25: 0 | V25: {=IFERROR(INDEX('사용자목록'!O:O, MATCH(A25, '사용자목록'!A:A, 0)),"아이언")} -> 아이언 | W25: 23 | X25: =if(Q25<W25, "🔼", if(Q25>W25, "🔽", ""))
A26: 유즈 | B26: 0 | C26: 2 | D26: 0 | E26: 2 | F26: 0 | G26: 0 | H26: 0 | I26: 0 | J26: =B26+D26+F26+H26 -> 0 | K26: =C26+E26+G26+I26 -> 4 | L26: =ROUND(IFERROR(J26/(J26+K26),0)*100,1) -> 0 | M26: =ROUND(IFERROR(B26/(B26+C26),0)*100,1) -> 0 | N26: =ROUND(IFERROR(D26/(D26+E26),0)*100,1) -> 0 | O26: =ROUND(IFERROR(F26/(F26+G26),0)*100,1) -> 0 | P26: =ROUND(IFERROR(H26/(I26+H26),0)*100,1) -> 0 | Q26: =IF(A26="미등록", "", COUNTIF(A$2:A26,"<>미등록")) -> 24 | R26: 0 | S26: 45986.968 | T26: N | U26: 0 | V26: {=IFERROR(INDEX('사용자목록'!O:O, MATCH(A26, '사용자목록'!A:A, 0)),"아이언")} -> 아이언 | W26: 24 | X26: =if(Q26<W26, "🔼", if(Q26>W26, "🔽", ""))

Sheet 전적확인_시즌14
A1: ID | B1: 드루_승 | C1: 드루_패 | D1: 어쎄_승 | E1: 어쎄_패 | F1: 네크_승 | G1: 네크_패 | H1: 슴딘_승 | I1: 슴딘_패 | J1: 종합_승 | K1: 종합_패 | L1: 종합_승률 | M1: 드루_승률 | N1: 어쎄_승률 | O1: 네크_승률 | P1: 슴딘_승률 | Q1: 순위 | R1: 점수 | S1: 날짜 | T1: 히든여부 | U1: 배치승리수 | V1: 티어 | W1: 이전 순위 | X1: 순위 증감
A2: 깡패 | B2: 21 | C2: 21 | D2: 24 | E2: 16 | F2: 13 | G2: 15 | H2: 33 | I2: 17 | J2: =B2+D2+F2+H2 -> 91 | K2: =C2+E2+G2+I2 -> 69 | L2: =ROUND(IFERROR(J2/(J2+K2),0)*100,1) -> 56.9 | M2: =ROUND(IFERROR(B2/(B2+C2),0)*100,1) -> 50 | N2: =ROUND(IFERROR(D2/(D2+E2),0)*100,1) -> 60 | O2: =ROUND(IFERROR(F2/(F2+G2),0)*100,1) -> 46.4 | P2: =ROUND(IFERROR(H2/(I2+H2),0)*100,1) -> 66 | Q2: =IF(A2="미등록", "", COUNTIF(A$2:A2,"<>미등록")) -> 1 | R2: 1724 | S2: 45970.981 | T2: N | U2: 10 | V2: {=IFERROR(INDEX('사용자목록'!O:O, MATCH(A2, '사용자목록'!A:A, 0)),"아이언")} -> 다이아 | W2: 1 | X2: =if(Q2<W2, "🔼", if(Q2>W2, "🔽", ""))
A3: 넘버 | B3: 20 | C3: 8 | D3: 14 | E3: 13 | F3: 16 | G3: 8 | H3: 19 | I3: 17 | J3: =B3+D3+F3+H3 -> 69 | K3: =C3+E3+G3+I3 -> 46 | L3: =ROUND(IFERROR(J3/(J3+K3),0)*100,1) -> 60 | M3: =ROUND(IFERROR(B3/(B3+C3),0)*100,1) -> 71.4 | N3: =ROUND(IFERROR(D3/(D3+E3),0)*100,1) -> 51.9 | O3: =ROUND(IFERROR(F3/(F3+G3),0)*100,1) -> 66.7 | P3: =ROUND(IFERROR(H3/(I3+H3),0)*100,1) -> 52.8 | Q3: =IF(A3="미등록", "", COUNTIF(A$2:A3,"<>미등록")) -> 2 | R3: 1693 | S3: 45970.981 | T3: N | U3: 12 | V3: {=IFERROR(INDEX('사용자목록'!O:O, MATCH(A3, '사용자목록'!A:A, 0)),"아이언")} -> 마스터 | W3: 3 | X3: =if(Q3<W3, "🔼", if(Q3>W3, "🔽", "")) -> 🔼
A4: 테리 | B4: 28 | C4: 13 | D4: 28 | E4: 11 | F4: 19 | G4: 12 | H4: 0 | I4: 0 | J4: =B4+D4+F4+H4 -> 75 | K4: =C4+E4+G4+I4 -> 36 | L4: =ROUND(IFERROR(J4/(J4+K4),0)*100,1) -> 67.6 | M4: =ROUND(IFERROR(B4/(B4+C4),0)*100,1) -> 68.3 | N4: =ROUND(IFERROR(D4/(D4+E4),0)*100,1) -> 71.8 | O4: =ROUND(IFERROR(F4/(F4+G4),0)*100,1) -> 61.3 | P4: =ROUND(IFERROR(H4/(I4+H4),0)*100,1) -> 0 | Q4: =IF(A4="미등록", "", COUNTIF(A$2:A4,"<>미등록")) -> 3 | R4: 1691 | S4: 45970.981 | T4: N | U4: 0 | V4: {=IFERROR(INDEX('사용자목록'!O:O, MATCH(A4, '사용자목록'!A:A, 0)),"아이언")} -> 마스터 | W4: 2 | X4: =if(Q4<W4, "🔼", if(Q4>W4, "🔽", "")) -> 🔽
A5: 원 | B5: 8 | C5: 5 | D5: 10 | E5: 5 | F5: 10 | G5: 3 | H5: 15 | I5: 6 | J5: =B5+D5+F5+H5 -> 43 | K5: =C5+E5+G5+I5 -> 19 | L5: =ROUND(IFERROR(J5/(J5+K5),0)*100,1) -> 69.4 | M5: =ROUND(IFERROR(B5/(B5+C5),0)*100,1) -> 61.5 | N5: =ROUND(IFERROR(D5/(D5+E5),0)*100,1) -> 66.7 | O5: =ROUND(IFERROR(F5/(F5+G5),0)*100,1) -> 76.9 | P5: =ROUND(IFERROR(H5/(I5+H5),0)*100,1) -> 71.4 | Q5: =IF(A5="미등록", "", COUNTIF(A$2:A5,"<>미등록")) -> 4 | R5: 1652 | S5: 45970.981 | T5: N | U5: 16 | V5: {=IFERROR(INDEX('사용자목록'!O:O, MATCH(A5, '사용자목록'!A:A, 0)),"아이언")} -> 마스터 | W5: 4 | X5: =if(Q5<W5, "🔼", if(Q5>W5, "🔽", ""))
A6: 솔 | B6: 15 | C6: 14 | D6: 13 | E6: 4 | F6: 10 | G6: 6 | H6: 13 | I6: 12 | J6: =B6+D6+F6+H6 -> 51 | K6: =C6+E6+G6+I6 -> 36 | L6: =ROUND(IFERROR(J6/(J6+K6),0)*100,1) -> 58.6 | M6: =ROUND(IFERROR(B6/(B6+C6),0)*100,1) -> 51.7 | N6: =ROUND(IFERROR(D6/(D6+E6),0)*100,1) -> 76.5 | O6: =ROUND(IFERROR(F6/(F6+G6),0)*100,1) -> 62.5 | P6: =ROUND(IFERROR(H6/(I6+H6),0)*100,1) -> 52 | Q6: =IF(A6="미등록", "", COUNTIF(A$2:A6,"<>미등록")) -> 5 | R6: 1631 | S6: 45970.96 | T6: N | U6: 10 | V6: {=IFERROR(INDEX('사용자목록'!O:O, MATCH(A6, '사용자목록'!A:A, 0)),"아이언")} -> 다이아 | W6: 5 | X6: =if(Q6<W6, "🔼", if(Q6>W6, "🔽", ""))
A7: 규식 | B7: 0 | C7: 0 | D7: 30 | E7: 15 | F7: 23 | G7: 17 | H7: 32 | I7: 23 | J7: =B7+D7+F7+H7 -> 85 | K7: =C7+E7+G7+I7 -> 55 | L7: =ROUND(IFERROR(J7/(J7+K7),0)*100,1) -> 60.7 | M7: =ROUND(IFERROR(B7/(B7+C7),0)*100,1) -> 0 | N7: =ROUND(IFERROR(D7/(D7+E7),0)*100,1) -> 66.7 | O7: =ROUND(IFERROR(F7/(F7+G7),0)*100,1) -> 57.5 | P7: =ROUND(IFERROR(H7/(I7+H7),0)*100,1) -> 58.2 | Q7: =IF(A7="미등록", "", COUNTIF(A$2:A7,"<>미등록")) -> 6 | R7: 1592 | S7: 45970.981 | T7: N | U7: 0 | V7: {=IFERROR(INDEX('사용자목록'!O:O, MATCH(A7, '사용자목록'!A:A, 0)),"아이언")} -> 마스터 | W7: 6 | X7: =if(Q7<W7, "🔼", if(Q7>W7, "🔽", ""))
A8: 짱구 | B8: 3 | C8: 12 | D8: 22 | E8: 16 | F8: 16 | G8: 11 | H8: 9 | I8: 13 | J8: =B8+D8+F8+H8 -> 50 | K8: =C8+E8+G8+I8 -> 52 | L8: =ROUND(IFERROR(J8/(J8+K8),0)*100,1) -> 49 | M8: =ROUND(IFERROR(B8/(B8+C8),0)*100,1) -> 20 | N8: =ROUND(IFERROR(D8/(D8+E8),0)*100,1) -> 57.9 | O8: =ROUND(IFERROR(F8/(F8+G8),0)*100,1) -> 59.3 | P8: =ROUND(IFERROR(H8/(I8+H8),0)*100,1) -> 40.9 | Q8: =IF(A8="미등록", "", COUNTIF(A$2:A8,"<>미등록")) -> 7 | R8: 1554 | S8: 45970.981 | T8: N | U8: 0 | V8: {=IFERROR(INDEX('사용자목록'!O:O, MATCH(A8, '사용자목록'!A:A, 0)),"아이언")} -> 골드 | W8: 7 | X8: =if(Q8<W8, "🔼", if(Q8>W8, "🔽", ""))
A9: 노인 | B9: 25 | C9: 11 | D9: 20 | E9: 21 | F9: 14 | G9: 16 | H9: 0 | I9: 0 | J9: =B9+D9+F9+H9 -> 59 | K9: =C9+E9+G9+I9 -> 48 | L9: =ROUND(IFERROR(J9/(J9+K9),0)*100,1) -> 55.1 | M9: =ROUND(IFERROR(B9/(B9+C9),0)*100,1) -> 69.4 | N9: =ROUND(IFERROR(D9/(D9+E9),0)*100,1) -> 48.8 | O9: =ROUND(IFERROR(F9/(F9+G9),0)*100,1) -> 46.7 | P9: =ROUND(IFERROR(H9/(I9+H9),0)*100,1) -> 0 | Q9: =IF(A9="미등록", "", COUNTIF(A$2:A9,"<>미등록")) -> 8 | R9: 1546 | S9: 45966.917 | T9: N | U9: 0 | V9: {=IFERROR(INDEX('사용자목록'!O:O, MATCH(A9, '사용자목록'!A:A, 0)),"아이언")} -> 다이아 | W9: 8 | X9: =if(Q9<W9, "🔼", if(Q9>W9, "🔽", ""))
A10: 기재 | B10: 15 | C10: 19 | D10: 0 | E10: 0 | F10: 19 | G10: 14 | H10: 25 | I10: 16 | J10: =B10+D10+F10+H10 -> 59 | K10: =C10+E10+G10+I10 -> 49 | L10: =ROUND(IFERROR(J10/(J10+K10),0)*100,1) -> 54.6 | M10: =ROUND(IFERROR(B10/(B10+C10),0)*100,1) -> 44.1 | N10: =ROUND(IFERROR(D10/(D10+E10),0)*100,1) -> 0 | O10: =ROUND(IFERROR(F10/(F10+G10),0)*100,1) -> 57.6 | P10: =ROUND(IFERROR(H10/(I10+H10),0)*100,1) -> 61 | Q10: =IF(A10="미등록", "", COUNTIF(A$2:A10,"<>미등록")) -> 9 | R10: 1475 | S10: 45970.942 | T10: N | U10: 0 | V10: {=IFERROR(INDEX('사용자목록'!O:O, MATCH(A10, '사용자목록'!A:A, 0)),"아이언")} -> 플래티넘 | W10: 9 | X10: =if(Q10<W10, "🔼", if(Q10>W10, "🔽", ""))
A11: 신형만 | B11: 21 | C11: 18 | D11: 13 | E11: 21 | F11: 14 | G11: 26 | H11: 21 | I11: 29 | J11: =B11+D11+F11+H11 -> 69 | K11: =C11+E11+G11+I11 -> 94 | L11: =ROUND(IFERROR(J11/(J11+K11),0)*100,1) -> 42.3 | M11: =ROUND(IFERROR(B11/(B11+C11),0)*100,1) -> 53.8 | N11: =ROUND(IFERROR(D11/(D11+E11),0)*100,1) -> 38.2 | O11: =ROUND(IFERROR(F11/(F11+G11),0)*100,1) -> 35 | P11: =ROUND(IFERROR(H11/(I11+H11),0)*100,1) -> 42 | Q11: =IF(A11="미등록", "", COUNTIF(A$2:A11,"<>미등록")) -> 10 | R11: 1460 | S11: 45970.981 | T11: N | U11: 7 | V11: {=IFERROR(INDEX('사용자목록'!O:O, MATCH(A11, '사용자목록'!A:A, 0)),"아이언")} -> 골드 | W11: 11 | X11: =if(Q11<W11, "🔼", if(Q11>W11, "🔽", "")) -> 🔼
A12: 참치 | B12: 3 | C12: 7 | D12: 9 | E12: 2 | F12: 3 | G12: 2 | H12: 5 | I12: 6 | J12: =B12+D12+F12+H12 -> 20 | K12: =C12+E12+G12+I12 -> 17 | L12: =ROUND(IFERROR(J12/(J12+K12),0)*100,1) -> 54.1 | M12: =ROUND(IFERROR(B12/(B12+C12),0)*100,1) -> 30 | N12: =ROUND(IFERROR(D12/(D12+E12),0)*100,1) -> 81.8 | O12: =ROUND(IFERROR(F12/(F12+G12),0)*100,1) -> 60 | P12: =ROUND(IFERROR(H12/(I12+H12),0)*100,1) -> 45.5 | Q12: =IF(A12="미등록", "", COUNTIF(A$2:A12,"<>미등록")) -> 11 | R12: 1435 | S12: 45966.052 | T12: N | U12: 10 | V12: {=IFERROR(INDEX('사용자목록'!O:O, MATCH(A12, '사용자목록'!A:A, 0)),"아이언")} -> 아이언 | W12: 10 | X12: =if(Q12<W12, "🔼", if(Q12>W12, "🔽", "")) -> 🔽
A13: 한메 | B13: 17 | C13: 16 | D13: 0 | E13: 0 | F13: 11 | G13: 15 | H13: 18 | I13: 25 | J13: =B13+D13+F13+H13 -> 46 | K13: =C13+E13+G13+I13 -> 56 | L13: =ROUND(IFERROR(J13/(J13+K13),0)*100,1) -> 45.1 | M13: =ROUND(IFERROR(B13/(B13+C13),0)*100,1) -> 51.5 | N13: =ROUND(IFERROR(D13/(D13+E13),0)*100,1) -> 0 | O13: =ROUND(IFERROR(F13/(F13+G13),0)*100,1) -> 42.3 | P13: =ROUND(IFERROR(H13/(I13+H13),0)*100,1) -> 41.9 | Q13: =IF(A13="미등록", "", COUNTIF(A$2:A13,"<>미등록")) -> 12 | R13: 1424 | S13: 45967.047 | T13: N | U13: 1 | V13: {=IFERROR(INDEX('사용자목록'!O:O, MATCH(A13, '사용자목록'!A:A, 0)),"아이언")} -> 골드 | W13: 12 | X13: =if(Q13<W13, "🔼", if(Q13>W13, "🔽", ""))
... A28: 새출발 | B28: 0 | C28: 2 | D28: 0 | E28: 3 | F28: 1 | G28: 1 | H28: 0 | I28: 0 | J28: =B28+D28+F28+H28 -> 1 | K28: =C28+E28+G28+I28 -> 6 | L28: =ROUND(IFERROR(J28/(J28+K28),0)*100,1) -> 14.3 | M28: =ROUND(IFERROR(B28/(B28+C28),0)*100,1) -> 0 | N28: =ROUND(IFERROR(D28/(D28+E28),0)*100,1) -> 0 | O28: =ROUND(IFERROR(F28/(F28+G28),0)*100,1) -> 50 | P28: =ROUND(IFERROR(H28/(I28+H28),0)*100,1) -> 0 | Q28: =IF(A28="미등록", "", COUNTIF(A$2:A28,"<>미등록")) -> 27 | R28: 0 | S28: 45931.028 | T28: N | U28: 0 | V28: {=IFERROR(INDEX('사용자목록'!O:O, MATCH(A28, '사용자목록'!A:A, 0)),"아이언")} -> 아이언 | W28: 27 | X28: =if(Q28<W28, "🔼", if(Q28>W28, "🔽", ""))
A29: 미등록 | B29: 0 | C29: 0 | D29: 0 | E29: 0 | F29: 0 | G29: 0 | H29: 0 | I29: 0 | J29: =B29+D29+F29+H29 -> 0 | K29: =C29+E29+G29+I29 -> 0 | L29: =ROUND(IFERROR(J29/(J29+K29),0)*100,1) -> 0 | M29: =ROUND(IFERROR(B29/(B29+C29),0)*100,1) -> 0 | N29: =ROUND(IFERROR(D29/(D29+E29),0)*100,1) -> 0 | O29: =ROUND(IFERROR(F29/(F29+G29),0)*100,1) -> 0 | P29: =ROUND(IFERROR(H29/(I29+H29),0)*100,1) -> 0 | Q29: =IF(A29="미등록", "", COUNTIF(A$2:A29,"<>미등록")) | R29: 0 | S29: 45953.033 | T29: Y | U29: 0 | V29: {=IFERROR(INDEX('사용자목록'!O:O, MATCH(A29, '사용자목록'!A:A, 0)),"아이언")} -> 아이언 | X29: =if(Q29<W29, "🔼", if(Q29>W29, "🔽", ""))
A30: 뼈해장국 | B30: 0 | C30: 0 | D30: 0 | E30: 0 | F30: 0 | G30: 1 | H30: 0 | I30: 1 | J30: =B30+D30+F30+H30 -> 0 | K30: =C30+E30+G30+I30 -> 2 | L30: =ROUND(IFERROR(J30/(J30+K30),0)*100,1) -> 0 | M30: =ROUND(IFERROR(B30/(B30+C30),0)*100,1) -> 0 | N30: =ROUND(IFERROR(D30/(D30+E30),0)*100,1) -> 0 | O30: =ROUND(IFERROR(F30/(F30+G30),0)*100,1) -> 0 | P30: =ROUND(IFERROR(H30/(I30+H30),0)*100,1) -> 0 | Q30: =IF(A30="미등록", "", COUNTIF(A$2:A30,"<>미등록")) -> 28 | R30: 0 | S30: 45932.024 | T30: N | U30: 0 | V30: {=IFERROR(INDEX('사용자목록'!O:O, MATCH(A30, '사용자목록'!A:A, 0)),"아이언")} -> 아이언 | W30: 28 | X30: =if(Q30<W30, "🔼", if(Q30>W30, "🔽", ""))
A31: 강화 | B31: 0 | C31: 0 | D31: 0 | E31: 0 | F31: 0 | G31: 1 | H31: 0 | I31: 1 | J31: =B31+D31+F31+H31 -> 0 | K31: =C31+E31+G31+I31 -> 2 | L31: =ROUND(IFERROR(J31/(J31+K31),0)*100,1) -> 0 | M31: =ROUND(IFERROR(B31/(B31+C31),0)*100,1) -> 0 | N31: =ROUND(IFERROR(D31/(D31+E31),0)*100,1) -> 0 | O31: =ROUND(IFERROR(F31/(F31+G31),0)*100,1) -> 0 | P31: =ROUND(IFERROR(H31/(I31+H31),0)*100,1) -> 0 | Q31: =IF(A31="미등록", "", COUNTIF(A$2:A31,"<>미등록")) -> 29 | R31: 0 | S31: 45937.081 | T31: N | U31: 0 | V31: {=IFERROR(INDEX('사용자목록'!O:O, MATCH(A31, '사용자목록'!A:A, 0)),"아이언")} -> 아이언 | W31: 29 | X31: =if(Q31<W31, "🔼", if(Q31>W31, "🔽", ""))
A32: 조네 | B32: 0 | C32: 2 | D32: 0 | E32: 2 | F32: 0 | G32: 0 | H32: 0 | I32: 0 | J32: =B32+D32+F32+H32 -> 0 | K32: =C32+E32+G32+I32 -> 4 | L32: =ROUND(IFERROR(J32/(J32+K32),0)*100,1) -> 0 | M32: =ROUND(IFERROR(B32/(B32+C32),0)*100,1) -> 0 | N32: =ROUND(IFERROR(D32/(D32+E32),0)*100,1) -> 0 | O32: =ROUND(IFERROR(F32/(F32+G32),0)*100,1) -> 0 | P32: =ROUND(IFERROR(H32/(I32+H32),0)*100,1) -> 0 | Q32: =IF(A32="미등록", "", COUNTIF(A$2:A32,"<>미등록")) -> 30 | R32: 0 | S32: 45951.094 | T32: N | U32: 0 | V32: {=IFERROR(INDEX('사용자목록'!O:O, MATCH(A32, '사용자목록'!A:A, 0)),"아이언")} -> 아이언 | W32: 30 | X32: =if(Q32<W32, "🔼", if(Q32>W32, "🔽", ""))

Sheet 전적이력
A1: # | B1: 경기날짜 | C1: 승리팀(스코어) | D1: WP | E1: 패배팀(스코어) | F1: LP | G1: 기록입력일 | H1: 시즌 | I1: 올캐릭 | J1: 승리_드루 | K1: 승리_어쎄 | L1: 승리_네크 | M1: 승리_슴딘 | N1: 패배_드루 | O1: 패배_어쎄 | P1: 패배_네크 | Q1: 패배_슴딘
A2: G260210002636 | B2: 2026-02-10 00:26 | C2: 신형만 (22)<br>박서 (-)<br>학생 (23)<br>규식 (16) | D2: 5 | E2: 깡패 (-16)<br>혀니 (-)<br>터미 (-)<br>민우 (-) | F2: 2 | G2: 46063.018 | H2: 시즌15 | I2: 깡패,신형만,학생,박서 | J2: =IFERROR(__xludf.DUMMYFUNCTION("ARRAYFORMULA(REGEXEXTRACT(SPLIT(C2, ""<br>""), ""([가-힣A-Za-z]+)""))"),"신형만") -> 신형만 | K2: =IFERROR(__xludf.DUMMYFUNCTION("""COMPUTED_VALUE"""),"박서") -> 박서 | L2: =IFERROR(__xludf.DUMMYFUNCTION("""COMPUTED_VALUE"""),"학생") -> 학생 | M2: =IFERROR(__xludf.DUMMYFUNCTION("""COMPUTED_VALUE"""),"규식") -> 규식 | N2: =IFERROR(__xludf.DUMMYFUNCTION("ARRAYFORMULA(REGEXEXTRACT(SPLIT(E2, ""<br>""), ""([가-힣A-Za-z]+)""))"),"깡패") -> 깡패 | O2: =IFERROR(__xludf.DUMMYFUNCTION("""COMPUTED_VALUE"""),"혀니") -> 혀니 | P2: =IFERROR(__xludf.DUMMYFUNCTION("""COMPUTED_VALUE"""),"터미") -> 터미 | Q2: =IFERROR(__xludf.DUMMYFUNCTION("""COMPUTED_VALUE"""),"민우") -> 민우
A3: G260209233706 | B3: 2026-02-09 23:37 | C3: 학생 (27)<br>혀니 (-)<br>테리 (18)<br>박서 (-) | D3: 5 | E3: 한메 (-)<br>깡패 (-19)<br>터미 (-)<br>신형만 (-17) | F3: 1 | G3: 46062.984 | H3: 시즌15 | I3: 깡패,신형만,학생,박서 | J3: =IFERROR(__xludf.DUMMYFUNCTION("ARRAYFORMULA(REGEXEXTRACT(SPLIT(C3, ""<br>""), ""([가-힣A-Za-z]+)""))"),"학생") -> 학생 | K3: =IFERROR(__xludf.DUMMYFUNCTION("""COMPUTED_VALUE"""),"혀니") -> 혀니 | L3: =IFERROR(__xludf.DUMMYFUNCTION("""COMPUTED_VALUE"""),"테리") -> 테리 | M3: =IFERROR(__xludf.DUMMYFUNCTION("""COMPUTED_VALUE"""),"박서") -> 박서 | N3: =IFERROR(__xludf.DUMMYFUNCTION("ARRAYFORMULA(REGEXEXTRACT(SPLIT(E3, ""<br>""), ""([가-힣A-Za-z]+)""))"),"한메") -> 한메 | O3: =IFERROR(__xludf.DUMMYFUNCTION("""COMPUTED_VALUE"""),"깡패") -> 깡패 | P3: =IFERROR(__xludf.DUMMYFUNCTION("""COMPUTED_VALUE"""),"터미") -> 터미 | Q3: =IFERROR(__xludf.DUMMYFUNCTION("""COMPUTED_VALUE"""),"신형만") -> 신형만
A4: G260209230157 | B4: 2026-02-09 23:01 | C4: 박서 (-)<br>신형만 (27)<br>학생 (29)<br>터미 (-) | D4: 5 | E4: 깡패 (-13)<br>테리 (-12)<br>한메 (-)<br>혀니 (-) | F4: 4 | G4: 46062.96 | H4: 시즌15 | I4: 깡패,신형만,학생,박서 | J4: =IFERROR(__xludf.DUMMYFUNCTION("ARRAYFORMULA(REGEXEXTRACT(SPLIT(C4, ""<br>""), ""([가-힣A-Za-z]+)""))"),"박서") -> 박서 | K4: =IFERROR(__xludf.DUMMYFUNCTION("""COMPUTED_VALUE"""),"신형만") -> 신형만 | L4: =IFERROR(__xludf.DUMMYFUNCTION("""COMPUTED_VALUE"""),"학생") -> 학생 | M4: =IFERROR(__xludf.DUMMYFUNCTION("""COMPUTED_VALUE"""),"터미") -> 터미 | N4: =IFERROR(__xludf.DUMMYFUNCTION("ARRAYFORMULA(REGEXEXTRACT(SPLIT(E4, ""<br>""), ""([가-힣A-Za-z]+)""))"),"깡패") -> 깡패 | O4: =IFERROR(__xludf.DUMMYFUNCTION("""COMPUTED_VALUE"""),"테리") -> 테리 | P4: =IFERROR(__xludf.DUMMYFUNCTION("""COMPUTED_VALUE"""),"한메") -> 한메 | Q4: =IFERROR(__xludf.DUMMYFUNCTION("""COMPUTED_VALUE"""),"혀니") -> 혀니
A5: G260209221951 | B5: 2026-02-09 22:19 | C5: 테리 (18)<br>박서 (-)<br>터미 (-)<br>한메 (-) | D5: 5 | E5: 학생 (-14)<br>깡패 (-17)<br>혀니 (-)<br>신형만 (-15) | F5: 2 | G5: 46062.931 | H5: 시즌15 | I5: 깡패,신형만,학생,박서 | J5: =IFERROR(__xludf.DUMMYFUNCTION("ARRAYFORMULA(REGEXEXTRACT(SPLIT(C5, ""<br>""), ""([가-힣A-Za-z]+)""))"),"테리") -> 테리 | K5: =IFERROR(__xludf.DUMMYFUNCTION("""COMPUTED_VALUE"""),"박서") -> 박서 | L5: =IFERROR(__xludf.DUMMYFUNCTION("""COMPUTED_VALUE"""),"터미") -> 터미 | M5: =IFERROR(__xludf.DUMMYFUNCTION("""COMPUTED_VALUE"""),"한메") -> 한메 | N5: =IFERROR(__xludf.DUMMYFUNCTION("ARRAYFORMULA(REGEXEXTRACT(SPLIT(E5, ""<br>""), ""([가-힣A-Za-z]+)""))"),"학생") -> 학생 | O5: =IFERROR(__xludf.DUMMYFUNCTION("""COMPUTED_VALUE"""),"깡패") -> 깡패 | P5: =IFERROR(__xludf.DUMMYFUNCTION("""COMPUTED_VALUE"""),"혀니") -> 혀니 | Q5: =IFERROR(__xludf.DUMMYFUNCTION("""COMPUTED_VALUE"""),"신형만") -> 신형만
A6: G260209213936 | B6: 2026-02-09 21:39 | C6: 테리 (16)<br>깡패 (16)<br>규식 (17)<br>터미 (-) | D6: 5 | E6: 박서 (-)<br>학생 (-15)<br>한메 (-)<br>기재 (-16) | F6: 1 | G6: 46062.902 | H6: 시즌15 | I6: 깡패,학생,박서 | J6: =IFERROR(__xludf.DUMMYFUNCTION("ARRAYFORMULA(REGEXEXTRACT(SPLIT(C6, ""<br>""), ""([가-힣A-Za-z]+)""))"),"테리") -> 테리 | K6: =IFERROR(__xludf.DUMMYFUNCTION("""COMPUTED_VALUE"""),"깡패") -> 깡패 | L6: =IFERROR(__xludf.DUMMYFUNCTION("""COMPUTED_VALUE"""),"규식") -> 규식 | M6: =IFERROR(__xludf.DUMMYFUNCTION("""COMPUTED_VALUE"""),"터미") -> 터미 | N6: =IFERROR(__xludf.DUMMYFUNCTION("ARRAYFORMULA(REGEXEXTRACT(SPLIT(E6, ""<br>""), ""([가-힣A-Za-z]+)""))"),"박서") -> 박서 | O6: =IFERROR(__xludf.DUMMYFUNCTION("""COMPUTED_VALUE"""),"학생") -> 학생 | P6: =IFERROR(__xludf.DUMMYFUNCTION("""COMPUTED_VALUE"""),"한메") -> 한메 | Q6: =IFERROR(__xludf.DUMMYFUNCTION("""COMPUTED_VALUE"""),"기재") -> 기재
A7: G260209211138 | B7: 2026-02-09 21:11 | C7: 깡패 (19)<br>규식 (20)<br>기재 (22)<br>한메 (-) | D7: 5 | E7: 터미 (-)<br>테리 (-15)<br>박서 (-)<br>학생 (-14) | F7: 2 | G7: 46062.883 | H7: 시즌15 | I7: 깡패,학생,박서 | J7: =IFERROR(__xludf.DUMMYFUNCTION("ARRAYFORMULA(REGEXEXTRACT(SPLIT(C7, ""<br>""), ""([가-힣A-Za-z]+)""))"),"깡패") -> 깡패 | K7: =IFERROR(__xludf.DUMMYFUNCTION("""COMPUTED_VALUE"""),"규식") -> 규식 | L7: =IFERROR(__xludf.DUMMYFUNCTION("""COMPUTED_VALUE"""),"기재") -> 기재 | M7: =IFERROR(__xludf.DUMMYFUNCTION("""COMPUTED_VALUE"""),"한메") -> 한메 | N7: =IFERROR(__xludf.DUMMYFUNCTION("ARRAYFORMULA(REGEXEXTRACT(SPLIT(E7, ""<br>""), ""([가-힣A-Za-z]+)""))"),"터미") -> 터미 | O7: =IFERROR(__xludf.DUMMYFUNCTION("""COMPUTED_VALUE"""),"테리") -> 테리 | P7: =IFERROR(__xludf.DUMMYFUNCTION("""COMPUTED_VALUE"""),"박서") -> 박서 | Q7: =IFERROR(__xludf.DUMMYFUNCTION("""COMPUTED_VALUE"""),"학생") -> 학생
A8: G260209050234 | B8: 2026-02-09 05:02 | C8: 참치 (264)<br>신형만 (25)<br>ACDC (22)<br>깡패 (21) | D8: 5 | E8: 민우 (-)<br>짱구 (-16)<br>수련 (-)<br>학생 (-18) | F8: 0 | G8: 46062.21 | H8: 시즌15 | I8: 깡패,신형만,참치,학생 | J8: =IFERROR(__xludf.DUMMYFUNCTION("ARRAYFORMULA(REGEXEXTRACT(SPLIT(C8, ""<br>""), ""([가-힣A-Za-z]+)""))"),"참치") -> 참치 | K8: =IFERROR(__xludf.DUMMYFUNCTION("""COMPUTED_VALUE"""),"신형만") -> 신형만 | L8: =IFERROR(__xludf.DUMMYFUNCTION("""COMPUTED_VALUE"""),"ACDC") -> ACDC | M8: =IFERROR(__xludf.DUMMYFUNCTION("""COMPUTED_VALUE"""),"깡패") -> 깡패 | N8: =IFERROR(__xludf.DUMMYFUNCTION("ARRAYFORMULA(REGEXEXTRACT(SPLIT(E8, ""<br>""), ""([가-힣A-Za-z]+)""))"),"민우") -> 민우 | O8: =IFERROR(__xludf.DUMMYFUNCTION("""COMPUTED_VALUE"""),"짱구") -> 짱구 | P8: =IFERROR(__xludf.DUMMYFUNCTION("""COMPUTED_VALUE"""),"수련") -> 수련 | Q8: =IFERROR(__xludf.DUMMYFUNCTION("""COMPUTED_VALUE"""),"학생") -> 학생
A9: G260209043628 | B9: 2026-02-09 04:36 | C9: ACDC (23)<br>학생 (25)<br>참치 (-)<br>민우 (-) | D9: 5 | E9: 깡패 (-11)<br>수련 (-)<br>짱구 (-10)<br>신형만 (-10) | F9: 4 | G9: 46062.192 | H9: 시즌15 | I9: 깡패,신형만,참치,학생 | J9: =IFERROR(__xludf.DUMMYFUNCTION("ARRAYFORMULA(REGEXEXTRACT(SPLIT(C9, ""<br>""), ""([가-힣A-Za-z]+)""))"),"ACDC") -> ACDC | K9: =IFERROR(__xludf.DUMMYFUNCTION("""COMPUTED_VALUE"""),"학생") -> 학생 | L9: =IFERROR(__xludf.DUMMYFUNCTION("""COMPUTED_VALUE"""),"참치") -> 참치 | M9: =IFERROR(__xludf.DUMMYFUNCTION("""COMPUTED_VALUE"""),"민우") -> 민우 | N9: =IFERROR(__xludf.DUMMYFUNCTION("ARRAYFORMULA(REGEXEXTRACT(SPLIT(E9, ""<br>""), ""([가-힣A-Za-z]+)""))"),"깡패") -> 깡패 | O9: =IFERROR(__xludf.DUMMYFUNCTION("""COMPUTED_VALUE"""),"수련") -> 수련 | P9: =IFERROR(__xludf.DUMMYFUNCTION("""COMPUTED_VALUE"""),"짱구") -> 짱구 | Q9: =IFERROR(__xludf.DUMMYFUNCTION("""COMPUTED_VALUE"""),"신형만") -> 신형만
A10: G260209010449 | B10: 2026-02-09 01:04 | C10: 참치 (-)<br>테리 (18)<br>학생 (25)<br>규식 (21) | D10: 5 | E10: 짱구 (-17)<br>깡패 (-19)<br>신형만 (-17)<br>ACDC (-16) | F10: 0 | G10: 46062.045 | H10: 시즌15 | I10: 깡패,짱구,신형만,학생,참치 | J10: =IFERROR(__xludf.DUMMYFUNCTION("ARRAYFORMULA(REGEXEXTRACT(SPLIT(C10, ""<br>""), ""([가-힣A-Za-z]+)""))"),"참치") -> 참치 | K10: =IFERROR(__xludf.DUMMYFUNCTION("""COMPUTED_VALUE"""),"테리") -> 테리 | L10: =IFERROR(__xludf.DUMMYFUNCTION("""COMPUTED_VALUE"""),"학생") -> 학생 | M10: =IFERROR(__xludf.DUMMYFUNCTION("""COMPUTED_VALUE"""),"규식") -> 규식 | N10: =IFERROR(__xludf.DUMMYFUNCTION("ARRAYFORMULA(REGEXEXTRACT(SPLIT(E10, ""<br>""), ""([가-힣A-Za-z]+)""))"),"짱구") -> 짱구 | O10: =IFERROR(__xludf.DUMMYFUNCTION("""COMPUTED_VALUE"""),"깡패") -> 깡패 | P10: =IFERROR(__xludf.DUMMYFUNCTION("""COMPUTED_VALUE"""),"신형만") -> 신형만 | Q10: =IFERROR(__xludf.DUMMYFUNCTION("""COMPUTED_VALUE"""),"ACDC") -> ACDC
A11: G260209004432 | B11: 2026-02-09 00:44 | C11: 테리 (22)<br>짱구 (32)<br>ACDC (26)<br>참치 (-) | D11: 5 | E11: 학생 (-18)<br>신형만 (-18)<br>기재 (-21)<br>깡패 (-20) | F11: 0 | G11: 46062.031 | H11: 시즌15 | I11: 깡패,짱구,신형만,학생,참치 | J11: =IFERROR(__xludf.DUMMYFUNCTION("ARRAYFORMULA(REGEXEXTRACT(SPLIT(C11, ""<br>""), ""([가-힣A-Za-z]+)""))"),"테리") -> 테리 | K11: =IFERROR(__xludf.DUMMYFUNCTION("""COMPUTED_VALUE"""),"짱구") -> 짱구 | L11: =IFERROR(__xludf.DUMMYFUNCTION("""COMPUTED_VALUE"""),"ACDC") -> ACDC | M11: =IFERROR(__xludf.DUMMYFUNCTION("""COMPUTED_VALUE"""),"참치") -> 참치 | N11: =IFERROR(__xludf.DUMMYFUNCTION("ARRAYFORMULA(REGEXEXTRACT(SPLIT(E11, ""<br>""), ""([가-힣A-Za-z]+)""))"),"학생") -> 학생 | O11: =IFERROR(__xludf.DUMMYFUNCTION("""COMPUTED_VALUE"""),"신형만") -> 신형만 | P11: =IFERROR(__xludf.DUMMYFUNCTION("""COMPUTED_VALUE"""),"기재") -> 기재 | Q11: =IFERROR(__xludf.DUMMYFUNCTION("""COMPUTED_VALUE"""),"깡패") -> 깡패
A12: G260209001550 | B12: 2026-02-09 00:15 | C12: 깡패 (23)<br>테리 (22)<br>짱구 (32)<br>신형만 (27) | D12: 5 | E12: ACDC (-17)<br>참치 (-)<br>학생 (-18)<br>기재 (192) | F12: 0 | G12: 46062.011 | H12: 시즌15 | I12: 깡패,짱구,신형만,학생,참치 | J12: =IFERROR(__xludf.DUMMYFUNCTION("ARRAYFORMULA(REGEXEXTRACT(SPLIT(C12, ""<br>""), ""([가-힣A-Za-z]+)""))"),"깡패") -> 깡패 | K12: =IFERROR(__xludf.DUMMYFUNCTION("""COMPUTED_VALUE"""),"테리") -> 테리 | L12: =IFERROR(__xludf.DUMMYFUNCTION("""COMPUTED_VALUE"""),"짱구") -> 짱구 | M12: =IFERROR(__xludf.DUMMYFUNCTION("""COMPUTED_VALUE"""),"신형만") -> 신형만 | N12: =IFERROR(__xludf.DUMMYFUNCTION("ARRAYFORMULA(REGEXEXTRACT(SPLIT(E12, ""<br>""), ""([가-힣A-Za-z]+)""))"),"ACDC") -> ACDC | O12: =IFERROR(__xludf.DUMMYFUNCTION("""COMPUTED_VALUE"""),"참치") -> 참치 | P12: =IFERROR(__xludf.DUMMYFUNCTION("""COMPUTED_VALUE"""),"학생") -> 학생 | Q12: =IFERROR(__xludf.DUMMYFUNCTION("""COMPUTED_VALUE"""),"기재") -> 기재
A13: G260208235257 | B13: 2026-02-08 23:52 | C13: 참치 (-)<br>짱구 (33)<br>테리 (23)<br>학생 (28) | D13: 5 | E13: 기재 (-)<br>깡패 (-20)<br>신형만 (-18)<br>ACDC (-17) | F13: 0 | G13: 46061.995 | H13: 시즌15 | I13: 깡패,짱구,신형만,학생,참치 | J13: =IFERROR(__xludf.DUMMYFUNCTION("ARRAYFORMULA(REGEXEXTRACT(SPLIT(C13, ""<br>""), ""([가-힣A-Za-z]+)""))"),"참치") -> 참치 | K13: =IFERROR(__xludf.DUMMYFUNCTION("""COMPUTED_VALUE"""),"짱구") -> 짱구 | L13: =IFERROR(__xludf.DUMMYFUNCTION("""COMPUTED_VALUE"""),"테리") -> 테리 | M13: =IFERROR(__xludf.DUMMYFUNCTION("""COMPUTED_VALUE"""),"학생") -> 학생 | N13: =IFERROR(__xludf.DUMMYFUNCTION("ARRAYFORMULA(REGEXEXTRACT(SPLIT(E13, ""<br>""), ""([가-힣A-Za-z]+)""))"),"기재") -> 기재 | O13: =IFERROR(__xludf.DUMMYFUNCTION("""COMPUTED_VALUE"""),"깡패") -> 깡패 | P13: =IFERROR(__xludf.DUMMYFUNCTION("""COMPUTED_VALUE"""),"신형만") -> 신형만 | Q13: =IFERROR(__xludf.DUMMYFUNCTION("""COMPUTED_VALUE"""),"ACDC") -> ACDC
A14: G260208232521 | B14: 2026-02-08 23:25 | C14: ovo (-)<br>혀니 (-)<br>원 (19)<br>깡패 (22) | D14: 5 | E14: 신형만 (-10)<br>학생 (-10)<br>웅 (-)<br>기재 (-) | F14: 4 | G14: 46061.976 | H14: 시즌15 | I14: 깡패,원,신형만,학생,웅 | J14: =IFERROR(__xludf.DUMMYFUNCTION("ARRAYFORMULA(REGEXEXTRACT(SPLIT(C14, ""<br>""), ""([가-힣A-Za-z]+)""))"),"ovo") -> ovo | K14: =IFERROR(__xludf.DUMMYFUNCTION("""COMPUTED_VALUE"""),"혀니") -> 혀니 | L14: =IFERROR(__xludf.DUMMYFUNCTION("""COMPUTED_VALUE"""),"원") -> 원 | M14: =IFERROR(__xludf.DUMMYFUNCTION("""COMPUTED_VALUE"""),"깡패") -> 깡패 | N14: =IFERROR(__xludf.DUMMYFUNCTION("ARRAYFORMULA(REGEXEXTRACT(SPLIT(E14, ""<br>""), ""([가-힣A-Za-z]+)""))"),"신형만") -> 신형만 | O14: =IFERROR(__xludf.DUMMYFUNCTION("""COMPUTED_VALUE"""),"학생") -> 학생 | P14: =IFERROR(__xludf.DUMMYFUNCTION("""COMPUTED_VALUE"""),"웅") -> 웅 | Q14: =IFERROR(__xludf.DUMMYFUNCTION("""COMPUTED_VALUE"""),"기재") -> 기재
A15: G260208225927 | B15: 2026-02-08 22:59 | C15: 테리 (23)<br>깡패 (23)<br>ovo (-)<br>신형만 (27) | D15: 5 | E15: 학생 (-14)<br>원 (-16)<br>혀니 (-)<br>웅 (-) | F15: 2 | G15: 46061.958 | H15: 시즌15 | I15: 깡패,원,신형만,학생,웅 | J15: =IFERROR(__xludf.DUMMYFUNCTION("ARRAYFORMULA(REGEXEXTRACT(SPLIT(C15, ""<br>""), ""([가-힣A-Za-z]+)""))"),"테리") -> 테리 | K15: =IFERROR(__xludf.DUMMYFUNCTION("""COMPUTED_VALUE"""),"깡패") -> 깡패 | L15: =IFERROR(__xludf.DUMMYFUNCTION("""COMPUTED_VALUE"""),"ovo") -> ovo | M15: =IFERROR(__xludf.DUMMYFUNCTION("""COMPUTED_VALUE"""),"신형만") -> 신형만 | N15: =IFERROR(__xludf.DUMMYFUNCTION("ARRAYFORMULA(REGEXEXTRACT(SPLIT(E15, ""<br>""), ""([가-힣A-Za-z]+)""))"),"학생") -> 학생 | O15: =IFERROR(__xludf.DUMMYFUNCTION("""COMPUTED_VALUE"""),"원") -> 원 | P15: =IFERROR(__xludf.DUMMYFUNCTION("""COMPUTED_VALUE"""),"혀니") -> 혀니 | Q15: =IFERROR(__xludf.DUMMYFUNCTION("""COMPUTED_VALUE"""),"웅") -> 웅
A16: G260208215520 | B16: 2026-02-08 21:55 | C16: 원 (17)<br>혀니 (-)<br>테리 (22)<br>깡패 (22) | D16: 5 | E16: 신형만 (-10)<br>학생 (-11)<br>짱구 (-9)<br>ovo (-) | F16: 4 | G16: 46061.913 | H16: 시즌15 | I16: 깡패,원,신형만,학생 | J16: =IFERROR(__xludf.DUMMYFUNCTION("ARRAYFORMULA(REGEXEXTRACT(SPLIT(C16, ""<br>""), ""([가-힣A-Za-z]+)""))"),"원") -> 원 | K16: =IFERROR(__xludf.DUMMYFUNCTION("""COMPUTED_VALUE"""),"혀니") -> 혀니 | L16: =IFERROR(__xludf.DUMMYFUNCTION("""COMPUTED_VALUE"""),"테리") -> 테리 | M16: =IFERROR(__xludf.DUMMYFUNCTION("""COMPUTED_VALUE"""),"깡패") -> 깡패 | N16: =IFERROR(__xludf.DUMMYFUNCTION("ARRAYFORMULA(REGEXEXTRACT(SPLIT(E16, ""<br>""), ""([가-힣A-Za-z]+)""))"),"신형만") -> 신형만 | O16: =IFERROR(__xludf.DUMMYFUNCTION("""COMPUTED_VALUE"""),"학생") -> 학생 | P16: =IFERROR(__xludf.DUMMYFUNCTION("""COMPUTED_VALUE"""),"짱구") -> 짱구 | Q16: =IFERROR(__xludf.DUMMYFUNCTION("""COMPUTED_VALUE"""),"ovo") -> ovo
A17: G260208210823 | B17: 2026-02-08 21:08 | C17: 학생 (23)<br>깡패 (21)<br>ovo (-)<br>원 (16) | D17: 5 | E17: 짱구 (-11)<br>테리 (-12)<br>혀니 (-)<br>신형만 (-12) | F17: 3 | G17: 46061.881 | H17: 시즌15 | I17: 깡패,원,신형만,학생 | J17: =IFERROR(__xludf.DUMMYFUNCTION("ARRAYFORMULA(REGEXEXTRACT(SPLIT(C17, ""<br>""), ""([가-힣A-Za-z]+)""))"),"학생") -> 학생 | K17: =IFERROR(__xludf.DUMMYFUNCTION("""COMPUTED_VALUE"""),"깡패") -> 깡패 | L17: =IFERROR(__xludf.DUMMYFUNCTION("""COMPUTED_VALUE"""),"ovo") -> ovo | M17: =IFERROR(__xludf.DUMMYFUNCTION("""COMPUTED_VALUE"""),"원") -> 원 | N17: =IFERROR(__xludf.DUMMYFUNCTION("ARRAYFORMULA(REGEXEXTRACT(SPLIT(E17, ""<br>""), ""([가-힣A-Za-z]+)""))"),"짱구") -> 짱구 | O17: =IFERROR(__xludf.DUMMYFUNCTION("""COMPUTED_VALUE"""),"테리") -> 테리 | P17: =IFERROR(__xludf.DUMMYFUNCTION("""COMPUTED_VALUE"""),"혀니") -> 혀니 | Q17: =IFERROR(__xludf.DUMMYFUNCTION("""COMPUTED_VALUE"""),"신형만") -> 신형만
A18: G260130213052 | B18: 2026-01-30 21:30 | C18: 참치 (-)<br>테리 (24)<br>신형만 (26)<br>ACDC (24) | D18: 5 | E18: 원 (-21)<br>학생 (-19)<br>짱구 (-17)<br>넘버 (-20) | F18: 0 | G18: 46052.897 | H18: 시즌15 | I18: 신형만,짱구,학생,원,넘버,참치 | J18: =IFERROR(__xludf.DUMMYFUNCTION("ARRAYFORMULA(REGEXEXTRACT(SPLIT(C18, ""<br>""), ""([가-힣A-Za-z]+)""))"),"참치") -> 참치 | K18: =IFERROR(__xludf.DUMMYFUNCTION("""COMPUTED_VALUE"""),"테리") -> 테리 | L18: =IFERROR(__xludf.DUMMYFUNCTION("""COMPUTED_VALUE"""),"신형만") -> 신형만 | M18: =IFERROR(__xludf.DUMMYFUNCTION("""COMPUTED_VALUE"""),"ACDC") -> ACDC | N18: =IFERROR(__xludf.DUMMYFUNCTION("ARRAYFORMULA(REGEXEXTRACT(SPLIT(E18, ""<br>""), ""([가-힣A-Za-z]+)""))"),"원") -> 원 | O18: =IFERROR(__xludf.DUMMYFUNCTION("""COMPUTED_VALUE"""),"학생") -> 학생 | P18: =IFERROR(__xludf.DUMMYFUNCTION("""COMPUTED_VALUE"""),"짱구") -> 짱구 | Q18: =IFERROR(__xludf.DUMMYFUNCTION("""COMPUTED_VALUE"""),"넘버") -> 넘버
A19: G260130211002 | B19: 2026-01-30 21:10 | C19: 짱구 (31)<br>신형만 (26)<br>테리 (23)<br>원 (360) | D19: 5 | E19: 학생 (-19)<br>규식 (-18)<br>넘버 (-20)<br>참치 (-) | F19: 0 | G19: 46052.882 | H19: 시즌15 | I19: 신형만,짱구,학생,원,넘버,참치 | J19: =IFERROR(__xludf.DUMMYFUNCTION("ARRAYFORMULA(REGEXEXTRACT(SPLIT(C19, ""<br>""), ""([가-힣A-Za-z]+)""))"),"짱구") -> 짱구 | K19: =IFERROR(__xludf.DUMMYFUNCTION("""COMPUTED_VALUE"""),"신형만") -> 신형만 | L19: =IFERROR(__xludf.DUMMYFUNCTION("""COMPUTED_VALUE"""),"테리") -> 테리 | M19: =IFERROR(__xludf.DUMMYFUNCTION("""COMPUTED_VALUE"""),"원") -> 원 | N19: =IFERROR(__xludf.DUMMYFUNCTION("ARRAYFORMULA(REGEXEXTRACT(SPLIT(E19, ""<br>""), ""([가-힣A-Za-z]+)""))"),"학생") -> 학생 | O19: =IFERROR(__xludf.DUMMYFUNCTION("""COMPUTED_VALUE"""),"규식") -> 규식 | P19: =IFERROR(__xludf.DUMMYFUNCTION("""COMPUTED_VALUE"""),"넘버") -> 넘버 | Q19: =IFERROR(__xludf.DUMMYFUNCTION("""COMPUTED_VALUE"""),"참치") -> 참치
A20: G260130204929 | B20: 2026-01-30 20:49 | C20: 원 (-)<br>테리 (22)<br>학생 (22)<br>규식 (20) | D20: 5 | E20: 넘버 (244)<br>참치 (-)<br>짱구 (-10)<br>신형만 (-11) | F20: 4 | G20: 46052.867 | H20: 시즌15 | I20: 신형만,짱구,학생,원,넘버,참치 | J20: =IFERROR(__xludf.DUMMYFUNCTION("ARRAYFORMULA(REGEXEXTRACT(SPLIT(C20, ""<br>""), ""([가-힣A-Za-z]+)""))"),"원") -> 원 | K20: =IFERROR(__xludf.DUMMYFUNCTION("""COMPUTED_VALUE"""),"테리") -> 테리 | L20: =IFERROR(__xludf.DUMMYFUNCTION("""COMPUTED_VALUE"""),"학생") -> 학생 | M20: =IFERROR(__xludf.DUMMYFUNCTION("""COMPUTED_VALUE"""),"규식") -> 규식 | N20: =IFERROR(__xludf.DUMMYFUNCTION("ARRAYFORMULA(REGEXEXTRACT(SPLIT(E20, ""<br>""), ""([가-힣A-Za-z]+)""))"),"넘버") -> 넘버 | O20: =IFERROR(__xludf.DUMMYFUNCTION("""COMPUTED_VALUE"""),"참치") -> 참치 | P20: =IFERROR(__xludf.DUMMYFUNCTION("""COMPUTED_VALUE"""),"짱구") -> 짱구 | Q20: =IFERROR(__xludf.DUMMYFUNCTION("""COMPUTED_VALUE"""),"신형만") -> 신형만
A21: G260127220153 | B21: 2026-01-27 22:01 | C21: 학생 (23)<br>규식 (20)<br>원 (-)<br>넘버 (-) | D21: 5 | E21: 테리 (-12)<br>ACDC (-12)<br>신형만 (-12)<br>참치 (-) | F21: 3 | G21: 46049.918 | H21: 시즌15 | I21: ACDC,신형만,넘버,원,학생,참치 | J21: =IFERROR(__xludf.DUMMYFUNCTION("ARRAYFORMULA(REGEXEXTRACT(SPLIT(C21, ""<br>""), ""([가-힣A-Za-z]+)""))"),"학생") -> 학생 | K21: =IFERROR(__xludf.DUMMYFUNCTION("""COMPUTED_VALUE"""),"규식") -> 규식 | L21: =IFERROR(__xludf.DUMMYFUNCTION("""COMPUTED_VALUE"""),"원") -> 원 | M21: =IFERROR(__xludf.DUMMYFUNCTION("""COMPUTED_VALUE"""),"넘버") -> 넘버 | N21: =IFERROR(__xludf.DUMMYFUNCTION("ARRAYFORMULA(REGEXEXTRACT(SPLIT(E21, ""<br>""), ""([가-힣A-Za-z]+)""))"),"테리") -> 테리 | O21: =IFERROR(__xludf.DUMMYFUNCTION("""COMPUTED_VALUE"""),"ACDC") -> ACDC | P21: =IFERROR(__xludf.DUMMYFUNCTION("""COMPUTED_VALUE"""),"신형만") -> 신형만 | Q21: =IFERROR(__xludf.DUMMYFUNCTION("""COMPUTED_VALUE"""),"참치") -> 참치
A22: G260127220038 | B22: 2026-01-27 22:00 | C22: 신형만 (23)<br>원 (-)<br>참치 (-)<br>학생 (23) | D22: 5 | E22: 넘버 (-)<br>테리 (-14)<br>오딘 (-)<br>ACDC (-14) | F22: 2 | G22: 46049.917 | H22: 시즌15 | I22: ACDC,오딘,신형만,넘버,원,학생,참치 | J22: =IFERROR(__xludf.DUMMYFUNCTION("ARRAYFORMULA(REGEXEXTRACT(SPLIT(C22, ""<br>""), ""([가-힣A-Za-z]+)""))"),"신형만") -> 신형만 | K22: =IFERROR(__xludf.DUMMYFUNCTION("""COMPUTED_VALUE"""),"원") -> 원 | L22: =IFERROR(__xludf.DUMMYFUNCTION("""COMPUTED_VALUE"""),"참치") -> 참치 | M22: =IFERROR(__xludf.DUMMYFUNCTION("""COMPUTED_VALUE"""),"학생") -> 학생 | N22: =IFERROR(__xludf.DUMMYFUNCTION("ARRAYFORMULA(REGEXEXTRACT(SPLIT(E22, ""<br>""), ""([가-힣A-Za-z]+)""))"),"넘버") -> 넘버 | O22: =IFERROR(__xludf.DUMMYFUNCTION("""COMPUTED_VALUE"""),"테리") -> 테리 | P22: =IFERROR(__xludf.DUMMYFUNCTION("""COMPUTED_VALUE"""),"오딘") -> 오딘 | Q22: =IFERROR(__xludf.DUMMYFUNCTION("""COMPUTED_VALUE"""),"ACDC") -> ACDC
A23: G260127215629 | B23: 2026-01-27 21:56 | C23: ACDC (27)<br>참치 (-)<br>테리 (23)<br>신형만 (26) | D23: 5 | E23: 원 (-)<br>넘버 (-)<br>학생 (-19)<br>오딘 (-) | F23: 0 | G23: 46049.914 | H23: 시즌15 | I23: ACDC,오딘,신형만,넘버,원,학생,참치 | J23: =IFERROR(__xludf.DUMMYFUNCTION("ARRAYFORMULA(REGEXEXTRACT(SPLIT(C23, ""<br>""), ""([가-힣A-Za-z]+)""))"),"ACDC") -> ACDC | K23: =IFERROR(__xludf.DUMMYFUNCTION("""COMPUTED_VALUE"""),"참치") -> 참치 | L23: =IFERROR(__xludf.DUMMYFUNCTION("""COMPUTED_VALUE"""),"테리") -> 테리 | M23: =IFERROR(__xludf.DUMMYFUNCTION("""COMPUTED_VALUE"""),"신형만") -> 신형만 | N23: =IFERROR(__xludf.DUMMYFUNCTION("ARRAYFORMULA(REGEXEXTRACT(SPLIT(E23, ""<br>""), ""([가-힣A-Za-z]+)""))"),"원") -> 원 | O23: =IFERROR(__xludf.DUMMYFUNCTION("""COMPUTED_VALUE"""),"넘버") -> 넘버 | P23: =IFERROR(__xludf.DUMMYFUNCTION("""COMPUTED_VALUE"""),"학생") -> 학생 | Q23: =IFERROR(__xludf.DUMMYFUNCTION("""COMPUTED_VALUE"""),"오딘") -> 오딘
A24: G260127215141 | B24: 2026-01-27 21:51 | C24: 테리 (22)<br>원 (-)<br>신형만 (25)<br>넘버 (-) | D24: 5 | E24: 학생 (-19)<br>오딘 (-)<br>참치 (-)<br>ACDC (-18) | F24: 0 | G24: 46049.91 | H24: 시즌15 | I24: ACDC,오딘,신형만,넘버,원,학생,참치 | J24: =IFERROR(__xludf.DUMMYFUNCTION("ARRAYFORMULA(REGEXEXTRACT(SPLIT(C24, ""<br>""), ""([가-힣A-Za-z]+)""))"),"테리") -> 테리 | K24: =IFERROR(__xludf.DUMMYFUNCTION("""COMPUTED_VALUE"""),"원") -> 원 | L24: =IFERROR(__xludf.DUMMYFUNCTION("""COMPUTED_VALUE"""),"신형만") -> 신형만 | M24: =IFERROR(__xludf.DUMMYFUNCTION("""COMPUTED_VALUE"""),"넘버") -> 넘버 | N24: =IFERROR(__xludf.DUMMYFUNCTION("ARRAYFORMULA(REGEXEXTRACT(SPLIT(E24, ""<br>""), ""([가-힣A-Za-z]+)""))"),"학생") -> 학생 | O24: =IFERROR(__xludf.DUMMYFUNCTION("""COMPUTED_VALUE"""),"오딘") -> 오딘 | P24: =IFERROR(__xludf.DUMMYFUNCTION("""COMPUTED_VALUE"""),"참치") -> 참치 | Q24: =IFERROR(__xludf.DUMMYFUNCTION("""COMPUTED_VALUE"""),"ACDC") -> ACDC
A25: G260121221414 | B25: 2026-01-21 22:14 | C25: ACDC (25)<br>넘버 (-)<br>학생 (22)<br>깡패 (20) | D25: 5 | E25: 테리 (-12)<br>원 (-)<br>규식 (-13)<br>한메 (-) | F25: 3 | G25: 46043.926 | H25: 시즌15 | I25: 깡패,넘버,원,ACDC,학생 | J25: =IFERROR(__xludf.DUMMYFUNCTION("ARRAYFORMULA(REGEXEXTRACT(SPLIT(C25, ""<br>""), ""([가-힣A-Za-z]+)""))"),"ACDC") -> ACDC | K25: =IFERROR(__xludf.DUMMYFUNCTION("""COMPUTED_VALUE"""),"넘버") -> 넘버 | L25: =IFERROR(__xludf.DUMMYFUNCTION("""COMPUTED_VALUE"""),"학생") -> 학생 | M25: =IFERROR(__xludf.DUMMYFUNCTION("""COMPUTED_VALUE"""),"깡패") -> 깡패 | N25: =IFERROR(__xludf.DUMMYFUNCTION("ARRAYFORMULA(REGEXEXTRACT(SPLIT(E25, ""<br>""), ""([가-힣A-Za-z]+)""))"),"테리") -> 테리 | O25: =IFERROR(__xludf.DUMMYFUNCTION("""COMPUTED_VALUE"""),"원") -> 원 | P25: =IFERROR(__xludf.DUMMYFUNCTION("""COMPUTED_VALUE"""),"규식") -> 규식 | Q25: =IFERROR(__xludf.DUMMYFUNCTION("""COMPUTED_VALUE"""),"한메") -> 한메
A26: G260121212258 | B26: 2026-01-21 21:22 | C26: 원 (-)<br>학생 (23)<br>깡패 (21)<br>한메 (-) | D26: 5 | E26: 테리 (-12)<br>넘버 (-)<br>ACDC (-12)<br>규식 (-13) | F26: 3 | G26: 46043.891 | H26: 시즌15 | I26: 깡패,넘버,원,ACDC,학생 | J26: =IFERROR(__xludf.DUMMYFUNCTION("ARRAYFORMULA(REGEXEXTRACT(SPLIT(C26, ""<br>""), ""([가-힣A-Za-z]+)""))"),"원") -> 원 | K26: =IFERROR(__xludf.DUMMYFUNCTION("""COMPUTED_VALUE"""),"학생") -> 학생 | L26: =IFERROR(__xludf.DUMMYFUNCTION("""COMPUTED_VALUE"""),"깡패") -> 깡패 | M26: =IFERROR(__xludf.DUMMYFUNCTION("""COMPUTED_VALUE"""),"한메") -> 한메 | N26: =IFERROR(__xludf.DUMMYFUNCTION("ARRAYFORMULA(REGEXEXTRACT(SPLIT(E26, ""<br>""), ""([가-힣A-Za-z]+)""))"),"테리") -> 테리 | O26: =IFERROR(__xludf.DUMMYFUNCTION("""COMPUTED_VALUE"""),"넘버") -> 넘버 | P26: =IFERROR(__xludf.DUMMYFUNCTION("""COMPUTED_VALUE"""),"ACDC") -> ACDC | Q26: =IFERROR(__xludf.DUMMYFUNCTION("""COMPUTED_VALUE"""),"규식") -> 규식
A27: G260121020028 | B27: 2026-01-21 02:00 | C27: ACDC (21)<br>깡패 (22)<br>넘버 (-)<br>짱구 (28) | D27: 5 | E27: 솔 (-)<br>학생 (-13)<br>테리 (-13)<br>신형만 (-13) | F27: 3 | G27: 46043.083 | H27: 시즌15 | I27: 깡패,넘버,신형만,솔,짱구,학생 | J27: =IFERROR(__xludf.DUMMYFUNCTION("ARRAYFORMULA(REGEXEXTRACT(SPLIT(C27, ""<br>""), ""([가-힣A-Za-z]+)""))"),"ACDC") -> ACDC | K27: =IFERROR(__xludf.DUMMYFUNCTION("""COMPUTED_VALUE"""),"깡패") -> 깡패 | L27: =IFERROR(__xludf.DUMMYFUNCTION("""COMPUTED_VALUE"""),"넘버") -> 넘버 | M27: =IFERROR(__xludf.DUMMYFUNCTION("""COMPUTED_VALUE"""),"짱구") -> 짱구 | N27: =IFERROR(__xludf.DUMMYFUNCTION("ARRAYFORMULA(REGEXEXTRACT(SPLIT(E27, ""<br>""), ""([가-힣A-Za-z]+)""))"),"솔") -> 솔 | O27: =IFERROR(__xludf.DUMMYFUNCTION("""COMPUTED_VALUE"""),"학생") -> 학생 | P27: =IFERROR(__xludf.DUMMYFUNCTION("""COMPUTED_VALUE"""),"테리") -> 테리 | Q27: =IFERROR(__xludf.DUMMYFUNCTION("""COMPUTED_VALUE"""),"신형만") -> 신형만
A28: G260121005515 | B28: 2026-01-21 00:55 | C28: 테리 (22)<br>짱구 (30)<br>솔 (-)<br>ACDC (27) | D28: 5 | E28: 학생 (-18)<br>신형만 (-18)<br>깡패 (-18)<br>넘버 (-) | F28: 1 | G28: 46043.038 | H28: 시즌15 | I28: 깡패,넘버,신형만,솔,짱구,학생,ACDC | J28: =IFERROR(__xludf.DUMMYFUNCTION("ARRAYFORMULA(REGEXEXTRACT(SPLIT(C28, ""<br>""), ""([가-힣A-Za-z]+)""))"),"테리") -> 테리 | K28: =IFERROR(__xludf.DUMMYFUNCTION("""COMPUTED_VALUE"""),"짱구") -> 짱구 | L28: =IFERROR(__xludf.DUMMYFUNCTION("""COMPUTED_VALUE"""),"솔") -> 솔 | M28: =IFERROR(__xludf.DUMMYFUNCTION("""COMPUTED_VALUE"""),"ACDC") -> ACDC | N28: =IFERROR(__xludf.DUMMYFUNCTION("ARRAYFORMULA(REGEXEXTRACT(SPLIT(E28, ""<br>""), ""([가-힣A-Za-z]+)""))"),"학생") -> 학생 | O28: =IFERROR(__xludf.DUMMYFUNCTION("""COMPUTED_VALUE"""),"신형만") -> 신형만 | P28: =IFERROR(__xludf.DUMMYFUNCTION("""COMPUTED_VALUE"""),"깡패") -> 깡패 | Q28: =IFERROR(__xludf.DUMMYFUNCTION("""COMPUTED_VALUE"""),"넘버") -> 넘버
A29: G260121002833 | B29: 2026-01-21 00:28 | C29: 깡패 (22)<br>넘버 (-)<br>ACDC (27)<br>솔 (-) | D29: 5 | E29: 신형만 (-14)<br>학생 (-14)<br>테리 (-13)<br>짱구 (-12) | F29: 3 | G29: 46043.019 | H29: 시즌15 | I29: 깡패,넘버,신형만,솔,짱구,학생,ACDC | J29: =IFERROR(__xludf.DUMMYFUNCTION("ARRAYFORMULA(REGEXEXTRACT(SPLIT(C29, ""<br>""), ""([가-힣A-Za-z]+)""))"),"깡패") -> 깡패 | K29: =IFERROR(__xludf.DUMMYFUNCTION("""COMPUTED_VALUE"""),"넘버") -> 넘버 | L29: =IFERROR(__xludf.DUMMYFUNCTION("""COMPUTED_VALUE"""),"ACDC") -> ACDC | M29: =IFERROR(__xludf.DUMMYFUNCTION("""COMPUTED_VALUE"""),"솔") -> 솔 | N29: =IFERROR(__xludf.DUMMYFUNCTION("ARRAYFORMULA(REGEXEXTRACT(SPLIT(E29, ""<br>""), ""([가-힣A-Za-z]+)""))"),"신형만") -> 신형만 | O29: =IFERROR(__xludf.DUMMYFUNCTION("""COMPUTED_VALUE"""),"학생") -> 학생 | P29: =IFERROR(__xludf.DUMMYFUNCTION("""COMPUTED_VALUE"""),"테리") -> 테리 | Q29: =IFERROR(__xludf.DUMMYFUNCTION("""COMPUTED_VALUE"""),"짱구") -> 짱구
A30: G260120234022 | B30: 2026-01-20 23:40 | C30: 학생 (21)<br>솔 (-)<br>넘버 (-)<br>원 (-) | D30: 5 | E30: 테리 (-11)<br>짱구 (-10)<br>깡패 (-12)<br>ACDC (-11) | F30: 4 | G30: 46042.986 | H30: 시즌15 | I30: 깡패,넘버,원,솔,짱구,학생,ACDC | J30: =IFERROR(__xludf.DUMMYFUNCTION("ARRAYFORMULA(REGEXEXTRACT(SPLIT(C30, ""<br>""), ""([가-힣A-Za-z]+)""))"),"학생") -> 학생 | K30: =IFERROR(__xludf.DUMMYFUNCTION("""COMPUTED_VALUE"""),"솔") -> 솔 | L30: =IFERROR(__xludf.DUMMYFUNCTION("""COMPUTED_VALUE"""),"넘버") -> 넘버 | M30: =IFERROR(__xludf.DUMMYFUNCTION("""COMPUTED_VALUE"""),"원") -> 원 | N30: =IFERROR(__xludf.DUMMYFUNCTION("ARRAYFORMULA(REGEXEXTRACT(SPLIT(E30, ""<br>""), ""([가-힣A-Za-z]+)""))"),"테리") -> 테리 | O30: =IFERROR(__xludf.DUMMYFUNCTION("""COMPUTED_VALUE"""),"짱구") -> 짱구 | P30: =IFERROR(__xludf.DUMMYFUNCTION("""COMPUTED_VALUE"""),"깡패") -> 깡패 | Q30: =IFERROR(__xludf.DUMMYFUNCTION("""COMPUTED_VALUE"""),"ACDC") -> ACDC
A31: G260120230308 | B31: 2026-01-20 23:03 | C31: 신형만 (23)<br>깡패 (21)<br>원 (-)<br>짱구 (28) | D31: 5 | E31: 솔 (-)<br>ACDC (-16)<br>테리 (-17)<br>학생 (-17) | F31: 1 | G31: 46042.96 | H31: 시즌15 | I31: 깡패,신형만,원,솔,짱구,학생,ACDC | J31: =IFERROR(__xludf.DUMMYFUNCTION("ARRAYFORMULA(REGEXEXTRACT(SPLIT(C31, ""<br>""), ""([가-힣A-Za-z]+)""))"),"신형만") -> 신형만 | K31: =IFERROR(__xludf.DUMMYFUNCTION("""COMPUTED_VALUE"""),"깡패") -> 깡패 | L31: =IFERROR(__xludf.DUMMYFUNCTION("""COMPUTED_VALUE"""),"원") -> 원 | M31: =IFERROR(__xludf.DUMMYFUNCTION("""COMPUTED_VALUE"""),"짱구") -> 짱구 | N31: =IFERROR(__xludf.DUMMYFUNCTION("ARRAYFORMULA(REGEXEXTRACT(SPLIT(E31, ""<br>""), ""([가-힣A-Za-z]+)""))"),"솔") -> 솔 | O31: =IFERROR(__xludf.DUMMYFUNCTION("""COMPUTED_VALUE"""),"ACDC") -> ACDC | P31: =IFERROR(__xludf.DUMMYFUNCTION("""COMPUTED_VALUE"""),"테리") -> 테리 | Q31: =IFERROR(__xludf.DUMMYFUNCTION("""COMPUTED_VALUE"""),"학생") -> 학생
A32: G260120222632 | B32: 2026-01-20 22:26 | C32: ACDC (27)<br>테리 (20)<br>깡패 (23)<br>원 (-) | D32: 5 | E32: 한메 (-)<br>학생 (-14)<br>신형만 (-13)<br>솔 (-) | F32: 3 | G32: 46042.935 | H32: 시즌15 | I32: 깡패,신형만,원,솔,학생,ACDC | J32: =IFERROR(__xludf.DUMMYFUNCTION("ARRAYFORMULA(REGEXEXTRACT(SPLIT(C32, ""<br>""), ""([가-힣A-Za-z]+)""))"),"ACDC") -> ACDC | K32: =IFERROR(__xludf.DUMMYFUNCTION("""COMPUTED_VALUE"""),"테리") -> 테리 | L32: =IFERROR(__xludf.DUMMYFUNCTION("""COMPUTED_VALUE"""),"깡패") -> 깡패 | M32: =IFERROR(__xludf.DUMMYFUNCTION("""COMPUTED_VALUE"""),"원") -> 원 | N32: =IFERROR(__xludf.DUMMYFUNCTION("ARRAYFORMULA(REGEXEXTRACT(SPLIT(E32, ""<br>""), ""([가-힣A-Za-z]+)""))"),"한메") -> 한메 | O32: =IFERROR(__xludf.DUMMYFUNCTION("""COMPUTED_VALUE"""),"학생") -> 학생 | P32: =IFERROR(__xludf.DUMMYFUNCTION("""COMPUTED_VALUE"""),"신형만") -> 신형만 | Q32: =IFERROR(__xludf.DUMMYFUNCTION("""COMPUTED_VALUE"""),"솔") -> 솔
A33: G260120213946 | B33: 2026-01-20 21:39 | C33: 깡패 (24)<br>넘버 (-)<br>신형만 (23)<br>ACDC (28) | D33: 5 | E33: 테리 (-15)<br>솔 (-)<br>학생 (-16)<br>한메 (-) | F33: 2 | G33: 46042.903 | H33: 시즌15 | I33: 깡패,신형만,넘버,솔,학생,ACDC | J33: =IFERROR(__xludf.DUMMYFUNCTION("ARRAYFORMULA(REGEXEXTRACT(SPLIT(C33, ""<br>""), ""([가-힣A-Za-z]+)""))"),"깡패") -> 깡패 | K33: =IFERROR(__xludf.DUMMYFUNCTION("""COMPUTED_VALUE"""),"넘버") -> 넘버 | L33: =IFERROR(__xludf.DUMMYFUNCTION("""COMPUTED_VALUE"""),"신형만") -> 신형만 | M33: =IFERROR(__xludf.DUMMYFUNCTION("""COMPUTED_VALUE"""),"ACDC") -> ACDC | N33: =IFERROR(__xludf.DUMMYFUNCTION("ARRAYFORMULA(REGEXEXTRACT(SPLIT(E33, ""<br>""), ""([가-힣A-Za-z]+)""))"),"테리") -> 테리 | O33: =IFERROR(__xludf.DUMMYFUNCTION("""COMPUTED_VALUE"""),"솔") -> 솔 | P33: =IFERROR(__xludf.DUMMYFUNCTION("""COMPUTED_VALUE"""),"학생") -> 학생 | Q33: =IFERROR(__xludf.DUMMYFUNCTION("""COMPUTED_VALUE"""),"한메") -> 한메
A34: G260120210203 | B34: 2026-01-20 21:02 | C34: ACDC (27)<br>테리 (19)<br>학생 (288)<br>신형만 (22) | D34: 5 | E34: 한메 (-)<br>깡패 (-19)<br>솔 (-)<br>넘버 (-) | F34: 0 | G34: 46042.876 | H34: 시즌15 | I34: 깡패,신형만,넘버,솔,학생,ACDC | J34: =IFERROR(__xludf.DUMMYFUNCTION("ARRAYFORMULA(REGEXEXTRACT(SPLIT(C34, ""<br>""), ""([가-힣A-Za-z]+)""))"),"ACDC") -> ACDC | K34: =IFERROR(__xludf.DUMMYFUNCTION("""COMPUTED_VALUE"""),"테리") -> 테리 | L34: =IFERROR(__xludf.DUMMYFUNCTION("""COMPUTED_VALUE"""),"학생") -> 학생 | M34: =IFERROR(__xludf.DUMMYFUNCTION("""COMPUTED_VALUE"""),"신형만") -> 신형만 | N34: =IFERROR(__xludf.DUMMYFUNCTION("ARRAYFORMULA(REGEXEXTRACT(SPLIT(E34, ""<br>""), ""([가-힣A-Za-z]+)""))"),"한메") -> 한메 | O34: =IFERROR(__xludf.DUMMYFUNCTION("""COMPUTED_VALUE"""),"깡패") -> 깡패 | P34: =IFERROR(__xludf.DUMMYFUNCTION("""COMPUTED_VALUE"""),"솔") -> 솔 | Q34: =IFERROR(__xludf.DUMMYFUNCTION("""COMPUTED_VALUE"""),"넘버") -> 넘버
A35: G260120204202 | B35: 2026-01-20 20:41 | C35: 학생 (-)<br>신형만 (22)<br>깡패 (21)<br>한메 (-) | D35: 5 | E35: 넘버 (-)<br>솔 (-)<br>테리 (-11)<br>ACDC (-10) | F35: 4 | G35: 46042.863 | H35: 시즌15 | I35: 깡패,신형만,넘버,솔,학생,ACDC | J35: =IFERROR(__xludf.DUMMYFUNCTION("ARRAYFORMULA(REGEXEXTRACT(SPLIT(C35, ""<br>""), ""([가-힣A-Za-z]+)""))"),"학생") -> 학생 | K35: =IFERROR(__xludf.DUMMYFUNCTION("""COMPUTED_VALUE"""),"신형만") -> 신형만 | L35: =IFERROR(__xludf.DUMMYFUNCTION("""COMPUTED_VALUE"""),"깡패") -> 깡패 | M35: =IFERROR(__xludf.DUMMYFUNCTION("""COMPUTED_VALUE"""),"한메") -> 한메 | N35: =IFERROR(__xludf.DUMMYFUNCTION("ARRAYFORMULA(REGEXEXTRACT(SPLIT(E35, ""<br>""), ""([가-힣A-Za-z]+)""))"),"넘버") -> 넘버 | O35: =IFERROR(__xludf.DUMMYFUNCTION("""COMPUTED_VALUE"""),"솔") -> 솔 | P35: =IFERROR(__xludf.DUMMYFUNCTION("""COMPUTED_VALUE"""),"테리") -> 테리 | Q35: =IFERROR(__xludf.DUMMYFUNCTION("""COMPUTED_VALUE"""),"ACDC") -> ACDC
A36: G260114231046 | B36: 2026-01-14 23:10 | C36: 테리 (19)<br>신형만 (24)<br>규식 (17)<br>솔 (-) | D36: 5 | E36: 짱구 (-10)<br>깡패 (-12)<br>ACDC (-11)<br>학생 (-) | F36: 4 | G36: 46036.966 | H36: 시즌15 | I36: 신형만,짱구,학생,깡패,ACDC,솔 | J36: =IFERROR(__xludf.DUMMYFUNCTION("ARRAYFORMULA(REGEXEXTRACT(SPLIT(C36, ""<br>""), ""([가-힣A-Za-z]+)""))"),"테리") -> 테리 | K36: =IFERROR(__xludf.DUMMYFUNCTION("""COMPUTED_VALUE"""),"신형만") -> 신형만 | L36: =IFERROR(__xludf.DUMMYFUNCTION("""COMPUTED_VALUE"""),"규식") -> 규식 | M36: =IFERROR(__xludf.DUMMYFUNCTION("""COMPUTED_VALUE"""),"솔") -> 솔 | N36: =IFERROR(__xludf.DUMMYFUNCTION("ARRAYFORMULA(REGEXEXTRACT(SPLIT(E36, ""<br>""), ""([가-힣A-Za-z]+)""))"),"짱구") -> 짱구 | O36: =IFERROR(__xludf.DUMMYFUNCTION("""COMPUTED_VALUE"""),"깡패") -> 깡패 | P36: =IFERROR(__xludf.DUMMYFUNCTION("""COMPUTED_VALUE"""),"ACDC") -> ACDC | Q36: =IFERROR(__xludf.DUMMYFUNCTION("""COMPUTED_VALUE"""),"학생") -> 학생
A37: G260114230908 | B37: 2026-01-14 23:09 | C37: 신형만 (23)<br>테리 (18)<br>넘버 (-)<br>ACDC (25) | D37: 5 | E37: 솔 (-)<br>학생 (-)<br>짱구 (-18)<br>규식 (308) | F37: 0 | G37: 46036.965 | H37: 시즌15 | I37: 신형만,짱구,학생,넘버,ACDC,솔 | J37: =IFERROR(__xludf.DUMMYFUNCTION("ARRAYFORMULA(REGEXEXTRACT(SPLIT(C37, ""<br>""), ""([가-힣A-Za-z]+)""))"),"신형만") -> 신형만 | K37: =IFERROR(__xludf.DUMMYFUNCTION("""COMPUTED_VALUE"""),"테리") -> 테리 | L37: =IFERROR(__xludf.DUMMYFUNCTION("""COMPUTED_VALUE"""),"넘버") -> 넘버 | M37: =IFERROR(__xludf.DUMMYFUNCTION("""COMPUTED_VALUE"""),"ACDC") -> ACDC | N37: =IFERROR(__xludf.DUMMYFUNCTION("ARRAYFORMULA(REGEXEXTRACT(SPLIT(E37, ""<br>""), ""([가-힣A-Za-z]+)""))"),"솔") -> 솔 | O37: =IFERROR(__xludf.DUMMYFUNCTION("""COMPUTED_VALUE"""),"학생") -> 학생 | P37: =IFERROR(__xludf.DUMMYFUNCTION("""COMPUTED_VALUE"""),"짱구") -> 짱구 | Q37: =IFERROR(__xludf.DUMMYFUNCTION("""COMPUTED_VALUE"""),"규식") -> 규식
A38: G260114230641 | B38: 2026-01-14 23:06 | C38: 테리 (17)<br>규식 (-)<br>ACDC (24)<br>짱구 (23) | D38: 5 | E38: 학생 (-)<br>신형만 (-13)<br>솔 (-)<br>넘버 (-) | F38: 3 | G38: 46036.963 | H38: 시즌15 | I38: 신형만,짱구,학생,넘버,ACDC,솔 | J38: =IFERROR(__xludf.DUMMYFUNCTION("ARRAYFORMULA(REGEXEXTRACT(SPLIT(C38, ""<br>""), ""([가-힣A-Za-z]+)""))"),"테리") -> 테리 | K38: =IFERROR(__xludf.DUMMYFUNCTION("""COMPUTED_VALUE"""),"규식") -> 규식 | L38: =IFERROR(__xludf.DUMMYFUNCTION("""COMPUTED_VALUE"""),"ACDC") -> ACDC | M38: =IFERROR(__xludf.DUMMYFUNCTION("""COMPUTED_VALUE"""),"짱구") -> 짱구 | N38: =IFERROR(__xludf.DUMMYFUNCTION("ARRAYFORMULA(REGEXEXTRACT(SPLIT(E38, ""<br>""), ""([가-힣A-Za-z]+)""))"),"학생") -> 학생 | O38: =IFERROR(__xludf.DUMMYFUNCTION("""COMPUTED_VALUE"""),"신형만") -> 신형만 | P38: =IFERROR(__xludf.DUMMYFUNCTION("""COMPUTED_VALUE"""),"솔") -> 솔 | Q38: =IFERROR(__xludf.DUMMYFUNCTION("""COMPUTED_VALUE"""),"넘버") -> 넘버
A39: G251210212447 | B39: 2025-12-10 21:24 | C39: 테리 (19)<br>학생 (-)<br>한메 (-)<br>신형만 (23) | D39: 5 | E39: 노인 (-)<br>오딘 (-)<br>규식 (-)<br>깡패 (-12) | F39: 4 | G39: 46001.892 | H39: 시즌15 | I39: 깡패,신형만,학생 | J39: =IFERROR(__xludf.DUMMYFUNCTION("ARRAYFORMULA(REGEXEXTRACT(SPLIT(C39, ""<br>""), ""([가-힣A-Za-z]+)""))"),"테리") -> 테리 | K39: =IFERROR(__xludf.DUMMYFUNCTION("""COMPUTED_VALUE"""),"학생") -> 학생 | L39: =IFERROR(__xludf.DUMMYFUNCTION("""COMPUTED_VALUE"""),"한메") -> 한메 | M39: =IFERROR(__xludf.DUMMYFUNCTION("""COMPUTED_VALUE"""),"신형만") -> 신형만 | N39: =IFERROR(__xludf.DUMMYFUNCTION("ARRAYFORMULA(REGEXEXTRACT(SPLIT(E39, ""<br>""), ""([가-힣A-Za-z]+)""))"),"노인") -> 노인 | O39: =IFERROR(__xludf.DUMMYFUNCTION("""COMPUTED_VALUE"""),"오딘") -> 오딘 | P39: =IFERROR(__xludf.DUMMYFUNCTION("""COMPUTED_VALUE"""),"규식") -> 규식 | Q39: =IFERROR(__xludf.DUMMYFUNCTION("""COMPUTED_VALUE"""),"깡패") -> 깡패
A40: G251210203915 | B40: 2025-12-10 20:39 | C40: 학생 (-)<br>깡패 (20)<br>테리 (20)<br>오딘 (-) | D40: 5 | E40: 한메 (-)<br>신형만 (-14)<br>노인 (-)<br>규식 (-) | F40: 2 | G40: 46001.86 | H40: 시즌15 | I40: 깡패,신형만,학생 | J40: =IFERROR(__xludf.DUMMYFUNCTION("ARRAYFORMULA(REGEXEXTRACT(SPLIT(C40, ""<br>""), ""([가-힣A-Za-z]+)""))"),"학생") -> 학생 | K40: =IFERROR(__xludf.DUMMYFUNCTION("""COMPUTED_VALUE"""),"깡패") -> 깡패 | L40: =IFERROR(__xludf.DUMMYFUNCTION("""COMPUTED_VALUE"""),"테리") -> 테리 | M40: =IFERROR(__xludf.DUMMYFUNCTION("""COMPUTED_VALUE"""),"오딘") -> 오딘 | N40: =IFERROR(__xludf.DUMMYFUNCTION("ARRAYFORMULA(REGEXEXTRACT(SPLIT(E40, ""<br>""), ""([가-힣A-Za-z]+)""))"),"한메") -> 한메 | O40: =IFERROR(__xludf.DUMMYFUNCTION("""COMPUTED_VALUE"""),"신형만") -> 신형만 | P40: =IFERROR(__xludf.DUMMYFUNCTION("""COMPUTED_VALUE"""),"노인") -> 노인 | Q40: =IFERROR(__xludf.DUMMYFUNCTION("""COMPUTED_VALUE"""),"규식") -> 규식
...

Sheet 시즌목록
A1: 과거시즌목록 | B1: 시작일 | C1: 마감일 | E1: 현재시즌 | F1: 시작일 | G1: 마감일 | H1: 티어 참조 시즌 | I1: 시즌 상태
A2: 시즌14 | B2: 25.09.27 | C2: 25.11.09 | E2: 시즌15 | F2: 25.11.10 | G2: 25.12.21 | H2: ="전적확인_" & A2 -> 전적확인_시즌14 | I2: 오픈
A3: 시즌13 | B3: 25.08.18 | C3: 25.09.27 | G3: ↑ 함수임. +40 시즌일정 맞춰서 넣으세욤
A4: 시즌12 | B4: 25.07.13 | C4: 25.08.17
A5: 시즌11 | B5: 25.05.10 | C5: 25.07.10
A6: 시즌10 | B6: 25.03.07 | C6: 25.04.27
A7: 시즌9 | B7: 25.01.29 | C7: 25.03.03
A8: 시즌8 | B8: 24.12.29 | C8: 25.01.27
A9: 시즌7 | B9: 24.11.24 | C9: 24.12.22
A10: 시즌6 | B10: 24.10.24 | C10: 24.11.17
A11: 시즌5 | B11: 24.09.02 | C11: 24.10.12
A12: 시즌4 | B12: 24.08.05 | C12: 24.08.28
A13: 시즌3 | B13: 24.07.16 | C13: 24.08.05
A14: 시즌2 | B14: 24.07.01 | C14: 24.07.16
A15: 시즌1 | B15: 24.06.11 | C15: 24.06.30
A16: 베타시즌 | B16: 24.06.02 | C16: 24.06.10

Sheet 듀오전적
A1: 시즌 | B1: 듀오조합 | C1: 승 | D1: 패 | E1: 승률
A2: 시즌15 | B2: 깡패&테리 | C2: 13 | D2: 5 | E2: =IFERROR(TEXT(C2/(C2+D2), "0.0%"), "N/A") -> 72.2%
A3: 시즌15 | B3: 신형만&테리 | C3: 13 | D3: 10 | E3: =IFERROR(TEXT(C3/(C3+D3), "0.0%"), "N/A") -> 56.5%
A4: 시즌15 | B4: 짱구&테리 | C4: 12 | D4: 8 | E4: =IFERROR(TEXT(C4/(C4+D4), "0.0%"), "N/A") -> 60.0%
A5: 시즌15 | B5: 테리&학생 | C5: 11 | D5: 6 | E5: =IFERROR(TEXT(C5/(C5+D5), "0.0%"), "N/A") -> 64.7%
A6: 시즌15 | B6: ACDC&테리 | C6: 11 | D6: 12 | E6: =IFERROR(TEXT(C6/(C6+D6), "0.0%"), "N/A") -> 47.8%
A7: 시즌15 | B7: 깡패&원 | C7: 10 | D7: 1 | E7: =IFERROR(TEXT(C7/(C7+D7), "0.0%"), "N/A") -> 90.9%
A8: 시즌15 | B8: 규식&테리 | C8: 10 | D8: 2 | E8: =IFERROR(TEXT(C8/(C8+D8), "0.0%"), "N/A") -> 83.3%
A9: 시즌15 | B9: ACDC&깡패 | C9: 10 | D9: 9 | E9: =IFERROR(TEXT(C9/(C9+D9), "0.0%"), "N/A") -> 52.6%
A10: 시즌15 | B10: 깡패&신형만 | C10: 10 | D10: 10 | E10: =IFERROR(TEXT(C10/(C10+D10), "0.0%"), "N/A") -> 50.0%
A11: 시즌15 | B11: 깡패&학생 | C11: 9 | D11: 5 | E11: =IFERROR(TEXT(C11/(C11+D11), "0.0%"), "N/A") -> 64.3%
A12: 시즌15 | B12: 신형만&학생 | C12: 9 | D12: 13 | E12: =IFERROR(TEXT(C12/(C12+D12), "0.0%"), "N/A") -> 40.9%
A13: 시즌15 | B13: 규식&학생 | C13: 8 | D13: 2 | E13: =IFERROR(TEXT(C13/(C13+D13), "0.0%"), "N/A") -> 80.0%
... A3367: 베타시즌 | B3367: 랄&전투쥐 | C3367: 0 | D3367: 1 | E3367: =IFERROR(TEXT(C3367/(C3367+D3367), "0.0%"), "N/A") -> 0.0%

Sheet 듀오전적전체
A1: =IFERROR(__xludf.DUMMYFUNCTION("QUERY('듀오전적'!A:D, ""select B, sum(C), sum(D), sum(C) / (sum(C) + sum(D)) where B is not null group by B order by sum(C) desc, sum(D) asc label sum(C) '총 승', sum(D) '총 패', sum(C) / (sum(C) + sum(D)) '승률' format sum(C) / (sum(C) + sum(D)) '0.0%'"", 1)"),"듀오조합") -> 듀오조합 | B1: =IFERROR(__xludf.DUMMYFUNCTION("""COMPUTED_VALUE"""),"총 승") -> 총 승 | C1: =IFERROR(__xludf.DUMMYFUNCTION("""COMPUTED_VALUE"""),"총 패") -> 총 패 | D1: =IFERROR(__xludf.DUMMYFUNCTION("""COMPUTED_VALUE"""),"승률") -> 승률
A2: =IFERROR(__xludf.DUMMYFUNCTION("""COMPUTED_VALUE"""),"깡패&신형만") -> 깡패&신형만 | B2: =IFERROR(__xludf.DUMMYFUNCTION("""COMPUTED_VALUE"""),271.0) -> 271 | C2: =IFERROR(__xludf.DUMMYFUNCTION("""COMPUTED_VALUE"""),234.0) -> 234 | D2: =IFERROR(__xludf.DUMMYFUNCTION("""COMPUTED_VALUE"""),0.5366336633663367) -> 0.53663366
A3: =IFERROR(__xludf.DUMMYFUNCTION("""COMPUTED_VALUE"""),"신형만&테리") -> 신형만&테리 | B3: =IFERROR(__xludf.DUMMYFUNCTION("""COMPUTED_VALUE"""),241.0) -> 241 | C3: =IFERROR(__xludf.DUMMYFUNCTION("""COMPUTED_VALUE"""),145.0) -> 145 | D3: =IFERROR(__xludf.DUMMYFUNCTION("""COMPUTED_VALUE"""),0.6243523316062176) -> 0.62435233
A4: =IFERROR(__xludf.DUMMYFUNCTION("""COMPUTED_VALUE"""),"깡패&테리") -> 깡패&테리 | B4: =IFERROR(__xludf.DUMMYFUNCTION("""COMPUTED_VALUE"""),222.0) -> 222 | C4: =IFERROR(__xludf.DUMMYFUNCTION("""COMPUTED_VALUE"""),118.0) -> 118 | D4: =IFERROR(__xludf.DUMMYFUNCTION("""COMPUTED_VALUE"""),0.6529411764705882) -> 0.65294118
